Workbook

Sheet Podsumowanie
A1: META - wycena metodą DCF
A2: Wszystkie liczby w tym arkuszu to formuły odwołujące się do pozostałych arkuszy.
A4: Wynik | B4: Wartość
A5: Wartość jednej akcji z DCF (USD) | B5: =DCF!$B$33 -> 344.99273
A6: Aktualny kurs (USD) | B6: =Założenia!$B$20 -> 709.33
A7: Różnica: wartość z DCF wobec kursu | B7: =B5/B6-1 -> -0.51363578
A8: WACC | B8: =Założenia!$B$29 -> 0.111
A9: Wzrost w okresie rezydualnym | B9: =Założenia!$B$18 -> 0.03
A10: Wartość firmy (mln USD) | B10: =DCF!$B$28 -> 849830.25
A11: Wartość kapitału własnego (mln USD) | B11: =DCF!$B$31 -> 872678.25
A12: Udział wartości rezydualnej w wartości firmy | B12: =DCF!$B$34 -> 0.88531068
A14: Kluczowe założenia | B14: Wartość
A15: Wzrost przychodów 2026 | B15: =Założenia!$B$5 -> 0.18
A16: Wzrost przychodów 2030 | B16: =Założenia!$F$5 -> 0.08
A17: Marża operacyjna 2026 | B17: =Założenia!$B$7 -> 0.38
A18: Marża operacyjna po 2030 | B18: =Założenia!$G$7 -> 0.36
A19: Nakłady inwestycyjne / przychody 2026 | B19: =Założenia!$B$9 -> 0.52
A20: Nakłady inwestycyjne / przychody po 2030 | B20: =Założenia!$G$9 -> 0.19
A21: Amortyzacja / przychody po 2030 | B21: =Założenia!$G$11 -> 0.16
A22: Stopa podatkowa | B22: =Założenia!$B$15 -> 0.15
A23: Stopa wolna od ryzyka (10Y UST) | B23: =Założenia!$B$19 -> 0.051
A24: Beta | B24: =Założenia!$B$16 -> 1.2
A25: Premia za ryzyko rynkowe | B25: =Założenia!$B$17 -> 0.05
D27: Dane do wykresów
D28: Rok | E28: Przychody (mln USD) | F28: Marża operacyjna | G28: FCF (mln USD)
D29: 2023 | E29: ='Dane historyczne'!$B$5 -> 134902 | F29: ='Dane historyczne'!$B$7 -> 0.34655528
D30: 2024 | E30: ='Dane historyczne'!$C$5 -> 164501 | F30: ='Dane historyczne'!$C$7 -> 0.42176035
D31: 2025 | E31: ='Dane historyczne'!$D$5 -> 200966 | F31: ='Dane historyczne'!$D$7 -> 0.41437855
D32: 2026 | E32: =DCF!$C$6 -> 237139.88 | F32: =DCF!$C$8 -> 0.38 | G32: =DCF!$C$17 -> -18259.771
D33: 2027 | E33: =DCF!$D$6 -> 272710.86 | F33: =DCF!$D$8 -> 0.37 | G33: =DCF!$D$17 -> 1227.1989
D34: 2028 | E34: =DCF!$E$6 -> 305436.17 | F34: =DCF!$E$8 -> 0.36 | G34: =DCF!$E$17 -> 26267.51
D35: 2029 | E35: =DCF!$F$6 -> 335979.78 | F35: =DCF!$F$8 -> 0.36 | G35: =DCF!$F$17 -> 62492.239
D36: 2030 | E36: =DCF!$G$6 -> 362858.16 | F36: =DCF!$G$8 -> 0.36 | G36: =DCF!$G$17 -> 89263.108
D39: Od wartości firmy do kapitału | E39: Podstawa (pomocnicza) | F39: Wartość (mln USD)
D40: PV FCF 2026-2030 | E40: =0 -> 0 | F40: =DCF!$B$22 -> 97466.452
D41: PV wartości rezydualnej | E41: =MIN(0,DCF!$B$22)+MAX(0,DCF!$B$22) -> 97466.452 | F41: =DCF!$B$27 -> 752363.8
D42: Wartość firmy | E42: =0 -> 0 | F42: =DCF!$B$28 -> 849830.25
D43: + Gotówka i papiery | E43: =DCF!$B$28 -> 849830.25 | F43: =DCF!$B$29 -> 81592
D44: - Dług | E44: =DCF!$B$28+DCF!$B$29+DCF!$B$30 -> 872678.25 | F44: =-DCF!$B$30 -> 58744
D45: Kapitał własny | E45: =0 -> 0 | F45: =DCF!$B$31 -> 872678.25
...

Sheet Dane historyczne
A1: META - dane historyczne z raportu 10-K (mln USD, jeśli nie podano inaczej)
A2: Niebieskie liczby pochodzą z ledgera; obok id wpisu, w komentarzu komórki cytat i strona źródła.
A4: Pozycja | B4: 2023 | C4: 2024 | D4: 2025 | E4: id 2023 | F4: id 2024 | G4: id 2025
A5: Przychody | B5: 134902 | C5: 164501 | D5: 200966 | E5: F-03 | F5: F-02 | G5: F-01
A6: Zysk operacyjny | B6: 46751 | C6: 69380 | D6: 83276 | E6: F-06 | F6: F-05 | G6: F-04
A7: Marża operacyjna | B7: =IF(B5=0,0,B6/B5) -> 0.34655528 | C7: =IF(C5=0,0,C6/C5) -> 0.42176035 | D7: =IF(D5=0,0,D6/D5) -> 0.41437855
A8: Wzrost przychodów r/r | C8: =IF(B5=0,0,C5/B5-1) -> 0.21941113 | D8: =IF(C5=0,0,D5/C5-1) -> 0.22167038
A10: Pozostałe fakty | B10: Wartość | C10: Jednostka | D10: Okres | E10: id
A11: Zysk netto | B11: 60458 | C11: mln USD | D11: 2025 | E11: F-07
A12: Amortyzacja (depreciation and amortization) | B12: 18616 | C12: mln USD | D12: 2025 | E12: F-08
A13: Nakłady inwestycyjne - zakup rzeczowych aktywów trwałych (wypływ gotówki, w raporcie w nawiasie, stąd wartość ujemna) | B13: -69691 | C13: mln USD | D13: 2025 | E13: F-09
A14: Zysk przed opodatkowaniem | B14: 85932 | C14: mln USD | D14: 2025 | E14: F-10
A15: Podatek dochodowy | B15: 25474 | C15: mln USD | D15: 2025 | E15: F-11
A16: Gotówka i ekwiwalenty gotówki na koniec roku | B16: 35873 | C16: mln USD | D16: 2025-12-31 | E16: F-12
A17: Papiery wartościowe (marketable securities) na koniec roku | B17: 45719 | C17: mln USD | D17: 2025-12-31 | E17: F-13
A18: Dług długoterminowy na koniec roku | B18: 58744 | C18: mln USD | D18: 2025-12-31 | E18: F-15
A19: Rzeczowe aktywa trwałe netto na koniec roku | B19: 176400 | C19: mln USD | D19: 2025-12-31 | E19: F-16
A20: Rzeczowe aktywa trwałe netto na koniec roku | B20: 121346 | C20: mln USD | D20: 2024-12-31 | E20: F-17
A21: Przychody segmentu Family of Apps | B21: 198759 | C21: mln USD | D21: 2025 | E21: F-18
A22: Zysk operacyjny segmentu Family of Apps | B22: 102469 | C22: mln USD | D22: 2025 | E22: F-19
... A32: Gotówka, ekwiwalenty i papiery wartościowe łącznie (raport podaje tę sumę tylko w mld USD) | B32: 81.59 | C32: mld USD | D32: 2025-12-31 | E32: F-14
A34: Wielkości wyliczone | B34: Wartość | C34: Jednostka | D34: Okres | E34: Formuła
A35: Gotówka i papiery wartościowe | B35: ='Dane historyczne'!$B$16+'Dane historyczne'!$B$17 -> 81592 | C35: mln USD | D35: 2025-12-31 | E35: F-12 + F-13
A36: Liczba akcji wszystkich klas | B36: ='Dane historyczne'!$B$25+'Dane historyczne'!$B$26 -> 2529555464 | C36: szt. | D36: 2026-01-23 | E36: F-22 + F-23
A37: Liczba akcji wszystkich klas | B37: =('Dane historyczne'!$B$25+'Dane historyczne'!$B$26)/10^6 -> 2529.5555 | C37: mln szt. | D37: 2026-01-23 | E37: (F-22 + F-23) / 1 mln
A38: Nakłady inwestycyjne / przychody | B38: =-'Dane historyczne'!$B$13/'Dane historyczne'!$D$5 -> 0.34678005 | C38: % | D38: 2025 | E38: -F-09 / F-01
A39: Amortyzacja / przychody | B39: ='Dane historyczne'!$B$12/'Dane historyczne'!$D$5 -> 0.092632585 | C39: % | D39: 2025 | E39: F-08 / F-01
A40: Efektywna stopa podatkowa (wyliczona) | B40: ='Dane historyczne'!$B$15/'Dane historyczne'!$B$14 -> 0.2964437 | C40: % | D40: 2025 | E40: F-11 / F-10

Sheet Założenia
A1: META - założenia modelu DCF
A2: Niebieskie komórki to założenia z ledgera (Z-..) i dane rynkowe (R-..). Zmiana wartości przelicza cały model. Uzasadnienie w komentarzu komórki i w tabeli poniżej.
A4: Prognoza | B4: 2026 | C4: 2027 | D4: 2028 | E4: 2029 | F4: 2030 | G4: Po 2030
A5: Wzrost przychodów r/r | B5: 0.18 | C5: 0.15 | D5: 0.12 | E5: 0.1 | F5: 0.08
A6: id wpisu | B6: Z-01 | C6: Z-02 | D6: Z-03 | E6: Z-04 | F6: Z-05
A7: Marża operacyjna | B7: 0.38 | C7: 0.37 | D7: 0.36 | E7: 0.36 | F7: 0.36 | G7: 0.36
A8: id wpisu | B8: Z-06 | C8: Z-07 | D8: Z-08 | E8: Z-09 | F8: Z-10 | G8: Z-11
A9: Nakłady inwestycyjne / przychody | B9: 0.52 | C9: 0.45 | D9: 0.38 | E9: 0.28 | F9: 0.22 | G9: 0.19
A10: id wpisu | B10: Z-12 | C10: Z-13 | D10: Z-14 | E10: Z-15 | F10: Z-16 | G10: Z-26
A11: Amortyzacja / przychody | B11: 0.12 | C11: 0.14 | D11: 0.16 | E11: 0.16 | F11: 0.16 | G11: 0.16
A12: id wpisu | B12: Z-17 | C12: Z-18 | D12: Z-19 | E12: Z-20 | F12: Z-21 | G12: Z-27
A14: Pozostałe założenia i dane rynkowe | B14: Wartość | C14: id | D14: Uwagi
A15: Stopa podatkowa do modelu DCF | B15: 0.15 | C15: Z-22 | D15: założenie
A16: Beta akcji META | B16: 1.2 | C16: Z-23 | D16: założenie
A17: Premia za ryzyko rynkowe (USA) | B17: 0.05 | C17: Z-24 | D17: założenie
A18: Wzrost w okresie rezydualnym (po 2030 r.) | B18: 0.03 | C18: Z-25 | D18: założenie
A19: Rentowność 10-letnich obligacji skarbowych USA (seria DGS10) | B19: 0.051 | C19: R-02 | D19: stan na 2026-10-15, pobrano 2026-10-17
A20: Kurs zamknięcia akcji META (Nasdaq), ostatnia sesja; zaokrąglony do centów | B20: 709.33 | C20: R-01 | D20: stan na 2026-10-16, pobrano 2026-10-17
A22: Koszt kapitału (WACC) | B22: Wartość | D22: Formuła
A23: Koszt kapitału własnego (CAPM) | B23: =Założenia!$B$19+Założenia!$B$16*Założenia!$B$17 -> 0.111 | D23: stopa wolna od ryzyka + beta × premia za ryzyko
A24: Dług długoterminowy (mln USD) | B24: ='Dane historyczne'!$B$18 -> 58744 | D24: F-15
A25: Kapitalizacja rynkowa (mln USD) | B25: =Założenia!$B$20*'Dane historyczne'!$B$37 -> 1794289.6 | D25: kurs × liczba akcji
A26: Udział długu w finansowaniu D/(D+E) | B26: =Założenia!$B$24/(Założenia!$B$24+Założenia!$B$25) -> 0.03170153 | D26: dług / (dług + kapitalizacja)
A27: Próg istotności długu (parametr modelu) | B27: 0.1 | D27: powyżej progu dług trzeba ująć w WACC
A28: Czy dług jest istotny? | B28: =IF(Założenia!$B$26>Założenia!$B$27,"TAK - dodaj koszt długu do WACC","NIE - WACC = koszt kapitału własnego") -> NIE - WACC = koszt kapitału własnego
A29: WACC | B29: =Założenia!$B$23 -> 0.111 | D29: równy kosztowi kapitału własnego, bo dług jest poniżej progu istotności
A31: Założenie | B31: id | C31: Uzasadnienie
A32: Wzrost przychodów r/r w 2026 r. | B32: Z-01 | C32: Przychody rosły o ok. 22% w 2025 r. (F-02 -> F-01) i ok. 22% w 2024 r. (F-03 -> F-02). Zakładamy lekkie spowolnienie przy tak dużej skali, a liczba użytkowników (F-28) rosła już tylko o 7%.
A33: Wzrost przychodów r/r w 2027 r. | B33: Z-02 | C33: Dalsze stopniowe spowolnienie: przychody prawie w całości pochodzą z reklam (F-35), a rynek reklamy rośnie wolniej niż Meta w ostatnich latach.
A34: Wzrost przychodów r/r w 2028 r. | B34: Z-03 | C34: Wzrost dalej słabnie wraz ze skalą biznesu; zakładamy, że AI wspiera skuteczność reklam, ale nie odwraca trendu spowolnienia.
A35: Wzrost przychodów r/r w 2029 r. | B35: Z-04 | C35: Kontynuacja łagodnego spowolnienia w stronę dojrzałej spółki.
A36: Wzrost przychodów r/r w 2030 r. | B36: Z-05 | C36: Ostatni rok prognozy; wzrost zbliża się do poziomu, z którego da się przejść do okresu rezydualnego (Z-25).
A37: Marża operacyjna w 2026 r. | B37: Z-06 | C37: Marża operacyjna w 2025 r. wyniosła 41% (F-27). Rekordowe nakłady (F-33, F-34) podnoszą amortyzację (Z-17 do Z-21), która obniża zysk operacyjny; do tego strata Reality Labs (F-21). Zakładamy marżę przed amortyzacją ok. 50-52% minus rosnąca amortyzacja.
A38: Marża operacyjna w 2027 r. | B38: Z-07 | C38: Marża operacyjna w 2025 r. wyniosła 41% (F-27). Rekordowe nakłady (F-33, F-34) podnoszą amortyzację (Z-17 do Z-21), która obniża zysk operacyjny; do tego strata Reality Labs (F-21). Zakładamy marżę przed amortyzacją ok. 50-52% minus rosnąca amortyzacja.
A39: Marża operacyjna w 2028 r. | B39: Z-08 | C39: Marża operacyjna w 2025 r. wyniosła 41% (F-27). Rekordowe nakłady (F-33, F-34) podnoszą amortyzację (Z-17 do Z-21), która obniża zysk operacyjny; do tego strata Reality Labs (F-21). Zakładamy marżę przed amortyzacją ok. 50-52% minus rosnąca amortyzacja.
A40: Marża operacyjna w 2029 r. | B40: Z-09 | C40: Marża operacyjna w 2025 r. wyniosła 41% (F-27). Rekordowe nakłady (F-33, F-34) podnoszą amortyzację (Z-17 do Z-21), która obniża zysk operacyjny; do tego strata Reality Labs (F-21). Zakładamy marżę przed amortyzacją ok. 50-52% minus rosnąca amortyzacja.
A41: Marża operacyjna w 2030 r. | B41: Z-10 | C41: Marża operacyjna w 2025 r. wyniosła 41% (F-27). Rekordowe nakłady (F-33, F-34) podnoszą amortyzację (Z-17 do Z-21), która obniża zysk operacyjny; do tego strata Reality Labs (F-21). Zakładamy marżę przed amortyzacją ok. 50-52% minus rosnąca amortyzacja.
A42: Marża operacyjna w okresie rezydualnym (po 2030 r.) | B42: Z-11 | C42: Zakładamy, że marża z 2030 r. (Z-10) utrzymuje się, bo amortyzacja w okresie rezydualnym (Z-27) jest taka sama jak w 2030 r.
... A58: Amortyzacja jako % przychodów w okresie rezydualnym | B58: Z-27 | C58: Pozostaje na poziomie z 2030 r. (Z-21): majątek zbudowany w latach 2026-2030 dalej się amortyzuje, a nakłady (Z-26) są tylko trochę wyższe niż amortyzacja.

Sheet DCF
A1: META - model DCF (mln USD)
A2: Wszystkie komórki to formuły. Dane wejściowe są w arkuszach 'Założenia' i 'Dane historyczne'. Przepływy dyskontowane na koniec każdego roku od końca 2025 r.
A4: Pozycja | B4: 2025 (raport) | C4: 2026 P | D4: 2027 P | E4: 2028 P | F4: 2029 P | G4: 2030 P | H4: Rezydualny (2031)
A5: Okres dyskontowy t (lata) | C5: =1 -> 1 | D5: =C5+1 -> 2 | E5: =D5+1 -> 3 | F5: =E5+1 -> 4 | G5: =F5+1 -> 5
A6: Przychody | B6: ='Dane historyczne'!$D$5 -> 200966 | C6: =B6*(1+C7) -> 237139.88 | D6: =C6*(1+D7) -> 272710.86 | E6: =D6*(1+E7) -> 305436.17 | F6: =E6*(1+F7) -> 335979.78 | G6: =F6*(1+G7) -> 362858.16 | H6: =G6*(1+H7) -> 373743.91
A7: Wzrost r/r | C7: =Założenia!$B$5 -> 0.18 | D7: =Założenia!$C$5 -> 0.15 | E7: =Założenia!$D$5 -> 0.12 | F7: =Założenia!$E$5 -> 0.1 | G7: =Założenia!$F$5 -> 0.08 | H7: =Założenia!$B$18 -> 0.03
A8: Marża operacyjna | C8: =Założenia!$B$7 -> 0.38 | D8: =Założenia!$C$7 -> 0.37 | E8: =Założenia!$D$7 -> 0.36 | F8: =Założenia!$E$7 -> 0.36 | G8: =Założenia!$F$7 -> 0.36 | H8: =Założenia!$G$7 -> 0.36
A9: Zysk operacyjny (EBIT) | C9: =C6*C8 -> 90113.154 | D9: =D6*D8 -> 100903.02 | E9: =E6*E8 -> 109957.02 | F9: =F6*F8 -> 120952.72 | G9: =G6*G8 -> 130628.94 | H9: =H6*H8 -> 134547.81
A10: Stopa podatkowa | C10: =Założenia!$B$15 -> 0.15 | D10: =Założenia!$B$15 -> 0.15 | E10: =Założenia!$B$15 -> 0.15 | F10: =Założenia!$B$15 -> 0.15 | G10: =Założenia!$B$15 -> 0.15 | H10: =Założenia!$B$15 -> 0.15
A11: Podatek | C11: =-C9*C10 -> -13516.973 | D11: =-D9*D10 -> -15135.453 | E11: =-E9*E10 -> -16493.553 | F11: =-F9*F10 -> -18142.908 | G11: =-G9*G10 -> -19594.341 | H11: =-H9*H10 -> -20182.171
A12: NOPAT | C12: =C9+C11 -> 76596.181 | D12: =D9+D11 -> 85767.566 | E12: =E9+E11 -> 93463.467 | F12: =F9+F11 -> 102809.81 | G12: =G9+G11 -> 111034.6 | H12: =H9+H11 -> 114365.64
A13: Amortyzacja / przychody | C13: =Założenia!$B$11 -> 0.12 | D13: =Założenia!$C$11 -> 0.14 | E13: =Założenia!$D$11 -> 0.16 | F13: =Założenia!$E$11 -> 0.16 | G13: =Założenia!$F$11 -> 0.16 | H13: =Założenia!$G$11 -> 0.16
A14: Amortyzacja | C14: =C6*C13 -> 28456.786 | D14: =D6*D13 -> 38179.521 | E14: =E6*E13 -> 48869.786 | F14: =F6*F13 -> 53756.765 | G14: =G6*G13 -> 58057.306 | H14: =H6*H13 -> 59799.026
A15: Nakłady inwestycyjne / przychody | C15: =Założenia!$B$9 -> 0.52 | D15: =Założenia!$C$9 -> 0.45 | E15: =Założenia!$D$9 -> 0.38 | F15: =Założenia!$E$9 -> 0.28 | G15: =Założenia!$F$9 -> 0.22 | H15: =Założenia!$G$9 -> 0.19
A16: Nakłady inwestycyjne | C16: =-C6*C15 -> -123312.74 | D16: =-D6*D15 -> -122719.89 | E16: =-E6*E15 -> -116065.74 | F16: =-F6*F15 -> -94074.339 | G16: =-G6*G15 -> -79828.796 | H16: =-H6*H15 -> -71011.343
A17: Wolne przepływy pieniężne (FCF) | C17: =C12+C14+C16 -> -18259.771 | D17: =D12+D14+D16 -> 1227.1989 | E17: =E12+E14+E16 -> 26267.51 | F17: =F12+F14+F16 -> 62492.239 | G17: =G12+G14+G16 -> 89263.108 | H17: =H12+H14+H16 -> 103153.32
A18: Czynnik dyskontowy | C18: =1/(1+$B$24)^C5 -> 0.90009001 | D18: =1/(1+$B$24)^D5 -> 0.81016202 | E18: =1/(1+$B$24)^E5 -> 0.72921874 | F18: =1/(1+$B$24)^F5 -> 0.65636251 | G18: =1/(1+$B$24)^G5 -> 0.59078533
A19: Wartość bieżąca FCF | C19: =C17*C18 -> -16435.437 | D19: =D17*D18 -> 994.22993 | E19: =E17*E18 -> 19154.761 | F19: =F17*F18 -> 41017.563 | G19: =G17*G18 -> 52735.335
A21: Wycena | B21: Wartość
A22: Suma wartości bieżących FCF 2026-2030 | B22: =SUM(C19:G19) -> 97466.452
A23: FCF okresu rezydualnego (rok 2031) | B23: =H17 -> 103153.32
A24: WACC | B24: =Założenia!$B$29 -> 0.111
A25: Wzrost w okresie rezydualnym (g) | B25: =Założenia!$B$18 -> 0.03
A26: Wartość rezydualna na koniec 2030 (Gordon: FCF 2031 / (WACC - g)) | B26: =IF(B24>B25,B23/(B24-B25),"WACC musi być większy od g") -> 1273497.8
A27: Wartość bieżąca wartości rezydualnej | B27: =B26*G18 -> 752363.8
A28: Wartość firmy (EV) | B28: =B22+B27 -> 849830.25
A29: + Gotówka i papiery wartościowe | B29: ='Dane historyczne'!$B$35 -> 81592
A30: - Dług długoterminowy | B30: =-'Dane historyczne'!$B$18 -> -58744
A31: Wartość kapitału własnego | B31: =B28+B29+B30 -> 872678.25
A32: Liczba akcji wszystkich klas (mln) | B32: ='Dane historyczne'!$B$37 -> 2529.5555
A33: Wartość jednej akcji (USD) | B33: =B31/B32 -> 344.99273
A34: Udział wartości rezydualnej w wartości firmy | B34: =B27/B28 -> 0.88531068

Sheet Wrażliwość
A1: META - wartość jednej akcji (USD) przy różnych WACC i wzroście rezydualnym
A2: Każda komórka liczy pełną wycenę formułą: przepływy 2026-2030 z arkusza DCF, wartość rezydualna dla danego g i WACC, gotówka, dług, liczba akcji. Środek tabeli = wariant bazowy.
A4: Krok WACC (parametr) | B4: 0.01
A5: Krok g (parametr) | B5: 0.005
C7: WACC →
A8: g ↓ | C8: =Założenia!$B$29+(-2)*$B$4 -> 0.091 | D8: =Założenia!$B$29+(-1)*$B$4 -> 0.101 | E8: =Założenia!$B$29+(0)*$B$4 -> 0.111 | F8: =Założenia!$B$29+(1)*$B$4 -> 0.121 | G8: =Założenia!$B$29+(2)*$B$4 -> 0.131
B9: =Założenia!$B$18+(-2)*$B$5 -> 0.02 | C9: =IF(C$8>$B9,(SUMPRODUCT(DCF!$C$17:$G$17/(1+C$8)^DCF!$C$5:$G$5)+DCF!$G$6*(1+$B9)*(DCF!$H$8*(1-DCF!$H$10)+DCF!$H$13-DCF!$H$15)/(C$8-$B9)/(1+C$8)^DCF!$G$5+DCF!$B$29+DCF!$B$30)/'Dane historyczne'!$B$37,"-") -> 419.06369 | D9: =IF(D$8>$B9,(SUMPRODUCT(DCF!$C$17:$G$17/(1+D$8)^DCF!$C$5:$G$5)+DCF!$G$6*(1+$B9)*(DCF!$H$8*(1-DCF!$H$10)+DCF!$H$13-DCF!$H$15)/(D$8-$B9)/(1+D$8)^DCF!$G$5+DCF!$B$29+DCF!$B$30)/'Dane historyczne'!$B$37,"-") -> 357.44404 | E9: =IF(E$8>$B9,(SUMPRODUCT(DCF!$C$17:$G$17/(1+E$8)^DCF!$C$5:$G$5)+DCF!$G$6*(1+$B9)*(DCF!$H$8*(1-DCF!$H$10)+DCF!$H$13-DCF!$H$15)/(E$8-$B9)/(1+E$8)^DCF!$G$5+DCF!$B$29+DCF!$B$30)/'Dane historyczne'!$B$37,"-") -> 309.73786 | F9: =IF(F$8>$B9,(SUMPRODUCT(DCF!$C$17:$G$17/(1+F$8)^DCF!$C$5:$G$5)+DCF!$G$6*(1+$B9)*(DCF!$H$8*(1-DCF!$H$10)+DCF!$H$13-DCF!$H$15)/(F$8-$B9)/(1+F$8)^DCF!$G$5+DCF!$B$29+DCF!$B$30)/'Dane historyczne'!$B$37,"-") -> 271.79613 | G9: =IF(G$8>$B9,(SUMPRODUCT(DCF!$C$17:$G$17/(1+G$8)^DCF!$C$5:$G$5)+DCF!$G$6*(1+$B9)*(DCF!$H$8*(1-DCF!$H$10)+DCF!$H$13-DCF!$H$15)/(G$8-$B9)/(1+G$8)^DCF!$G$5+DCF!$B$29+DCF!$B$30)/'Dane historyczne'!$B$37,"-") -> 240.96583
B10: =Założenia!$B$18+(-1)*$B$5 -> 0.025 | C10: =IF(C$8>$B10,(SUMPRODUCT(DCF!$C$17:$G$17/(1+C$8)^DCF!$C$5:$G$5)+DCF!$G$6*(1+$B10)*(DCF!$H$8*(1-DCF!$H$10)+DCF!$H$13-DCF!$H$15)/(C$8-$B10)/(1+C$8)^DCF!$G$5+DCF!$B$29+DCF!$B$30)/'Dane historyczne'!$B$37,"-") -> 448.88114 | D10: =IF(D$8>$B10,(SUMPRODUCT(DCF!$C$17:$G$17/(1+D$8)^DCF!$C$5:$G$5)+DCF!$G$6*(1+$B10)*(DCF!$H$8*(1-DCF!$H$10)+DCF!$H$13-DCF!$H$15)/(D$8-$B10)/(1+D$8)^DCF!$G$5+DCF!$B$29+DCF!$B$30)/'Dane historyczne'!$B$37,"-") -> 379.32789 | E10: =IF(E$8>$B10,(SUMPRODUCT(DCF!$C$17:$G$17/(1+E$8)^DCF!$C$5:$G$5)+DCF!$G$6*(1+$B10)*(DCF!$H$8*(1-DCF!$H$10)+DCF!$H$13-DCF!$H$15)/(E$8-$B10)/(1+E$8)^DCF!$G$5+DCF!$B$29+DCF!$B$30)/'Dane historyczne'!$B$37,"-") -> 326.34045 | F10: =IF(F$8>$B10,(SUMPRODUCT(DCF!$C$17:$G$17/(1+F$8)^DCF!$C$5:$G$5)+DCF!$G$6*(1+$B10)*(DCF!$H$8*(1-DCF!$H$10)+DCF!$H$13-DCF!$H$15)/(F$8-$B10)/(1+F$8)^DCF!$G$5+DCF!$B$29+DCF!$B$30)/'Dane historyczne'!$B$37,"-") -> 284.72489 | G10: =IF(G$8>$B10,(SUMPRODUCT(DCF!$C$17:$G$17/(1+G$8)^DCF!$C$5:$G$5)+DCF!$G$6*(1+$B10)*(DCF!$H$8*(1-DCF!$H$10)+DCF!$H$13-DCF!$H$15)/(G$8-$B10)/(1+G$8)^DCF!$G$5+DCF!$B$29+DCF!$B$30)/'Dane historyczne'!$B$37,"-") -> 251.24819
B11: =Założenia!$B$18+(0)*$B$5 -> 0.03 | C11: =IF(C$8>$B11,(SUMPRODUCT(DCF!$C$17:$G$17/(1+C$8)^DCF!$C$5:$G$5)+DCF!$G$6*(1+$B11)*(DCF!$H$8*(1-DCF!$H$10)+DCF!$H$13-DCF!$H$15)/(C$8-$B11)/(1+C$8)^DCF!$G$5+DCF!$B$29+DCF!$B$30)/'Dane historyczne'!$B$37,"-") -> 483.5867 | D11: =IF(D$8>$B11,(SUMPRODUCT(DCF!$C$17:$G$17/(1+D$8)^DCF!$C$5:$G$5)+DCF!$G$6*(1+$B11)*(DCF!$H$8*(1-DCF!$H$10)+DCF!$H$13-DCF!$H$15)/(D$8-$B11)/(1+D$8)^DCF!$G$5+DCF!$B$29+DCF!$B$30)/'Dane historyczne'!$B$37,"-") -> 404.29399 | E11: =IF(E$8>$B11,(SUMPRODUCT(DCF!$C$17:$G$17/(1+E$8)^DCF!$C$5:$G$5)+DCF!$G$6*(1+$B11)*(DCF!$H$8*(1-DCF!$H$10)+DCF!$H$13-DCF!$H$15)/(E$8-$B11)/(1+E$8)^DCF!$G$5+DCF!$B$29+DCF!$B$30)/'Dane historyczne'!$B$37,"-") -> 344.99273 | F11: =IF(F$8>$B11,(SUMPRODUCT(DCF!$C$17:$G$17/(1+F$8)^DCF!$C$5:$G$5)+DCF!$G$6*(1+$B11)*(DCF!$H$8*(1-DCF!$H$10)+DCF!$H$13-DCF!$H$15)/(F$8-$B11)/(1+F$8)^DCF!$G$5+DCF!$B$29+DCF!$B$30)/'Dane historyczne'!$B$37,"-") -> 299.07439 | G11: =IF(G$8>$B11,(SUMPRODUCT(DCF!$C$17:$G$17/(1+G$8)^DCF!$C$5:$G$5)+DCF!$G$6*(1+$B11)*(DCF!$H$8*(1-DCF!$H$10)+DCF!$H$13-DCF!$H$15)/(G$8-$B11)/(1+G$8)^DCF!$G$5+DCF!$B$29+DCF!$B$30)/'Dane historyczne'!$B$37,"-") -> 262.54859
B12: =Założenia!$B$18+(1)*$B$5 -> 0.035 | C12: =IF(C$8>$B12,(SUMPRODUCT(DCF!$C$17:$G$17/(1+C$8)^DCF!$C$5:$G$5)+DCF!$G$6*(1+$B12)*(DCF!$H$8*(1-DCF!$H$10)+DCF!$H$13-DCF!$H$15)/(C$8-$B12)/(1+C$8)^DCF!$G$5+DCF!$B$29+DCF!$B$30)/'Dane historyczne'!$B$37,"-") -> 524.48967 | D12: =IF(D$8>$B12,(SUMPRODUCT(DCF!$C$17:$G$17/(1+D$8)^DCF!$C$5:$G$5)+DCF!$G$6*(1+$B12)*(DCF!$H$8*(1-DCF!$H$10)+DCF!$H$13-DCF!$H$15)/(D$8-$B12)/(1+D$8)^DCF!$G$5+DCF!$B$29+DCF!$B$30)/'Dane historyczne'!$B$37,"-") -> 433.04282 | E12: =IF(E$8>$B12,(SUMPRODUCT(DCF!$C$17:$G$17/(1+E$8)^DCF!$C$5:$G$5)+DCF!$G$6*(1+$B12)*(DCF!$H$8*(1-DCF!$H$10)+DCF!$H$13-DCF!$H$15)/(E$8-$B12)/(1+E$8)^DCF!$G$5+DCF!$B$29+DCF!$B$30)/'Dane historyczne'!$B$37,"-") -> 366.09927 | F12: =IF(F$8>$B12,(SUMPRODUCT(DCF!$C$17:$G$17/(1+F$8)^DCF!$C$5:$G$5)+DCF!$G$6*(1+$B12)*(DCF!$H$8*(1-DCF!$H$10)+DCF!$H$13-DCF!$H$15)/(F$8-$B12)/(1+F$8)^DCF!$G$5+DCF!$B$29+DCF!$B$30)/'Dane historyczne'!$B$37,"-") -> 315.09243 | G12: =IF(G$8>$B12,(SUMPRODUCT(DCF!$C$17:$G$17/(1+G$8)^DCF!$C$5:$G$5)+DCF!$G$6*(1+$B12)*(DCF!$H$8*(1-DCF!$H$10)+DCF!$H$13-DCF!$H$15)/(G$8-$B12)/(1+G$8)^DCF!$G$5+DCF!$B$29+DCF!$B$30)/'Dane historyczne'!$B$37,"-") -> 275.02613
B13: =Założenia!$B$18+(2)*$B$5 -> 0.04 | C13: =IF(C$8>$B13,(SUMPRODUCT(DCF!$C$17:$G$17/(1+C$8)^DCF!$C$5:$G$5)+DCF!$G$6*(1+$B13)*(DCF!$H$8*(1-DCF!$H$10)+DCF!$H$13-DCF!$H$15)/(C$8-$B13)/(1+C$8)^DCF!$G$5+DCF!$B$29+DCF!$B$30)/'Dane historyczne'!$B$37,"-") -> 573.41284 | D13: =IF(D$8>$B13,(SUMPRODUCT(DCF!$C$17:$G$17/(1+D$8)^DCF!$C$5:$G$5)+DCF!$G$6*(1+$B13)*(DCF!$H$8*(1-DCF!$H$10)+DCF!$H$13-DCF!$H$15)/(D$8-$B13)/(1+D$8)^DCF!$G$5+DCF!$B$29+DCF!$B$30)/'Dane historyczne'!$B$37,"-") -> 466.50458 | E13: =IF(E$8>$B13,(SUMPRODUCT(DCF!$C$17:$G$17/(1+E$8)^DCF!$C$5:$G$5)+DCF!$G$6*(1+$B13)*(DCF!$H$8*(1-DCF!$H$10)+DCF!$H$13-DCF!$H$15)/(E$8-$B13)/(1+E$8)^DCF!$G$5+DCF!$B$29+DCF!$B$30)/'Dane historyczne'!$B$37,"-") -> 390.17855 | F13: =IF(F$8>$B13,(SUMPRODUCT(DCF!$C$17:$G$17/(1+F$8)^DCF!$C$5:$G$5)+DCF!$G$6*(1+$B13)*(DCF!$H$8*(1-DCF!$H$10)+DCF!$H$13-DCF!$H$15)/(F$8-$B13)/(1+F$8)^DCF!$G$5+DCF!$B$29+DCF!$B$30)/'Dane historyczne'!$B$37,"-") -> 333.08801 | G13: =IF(G$8>$B13,(SUMPRODUCT(DCF!$C$17:$G$17/(1+G$8)^DCF!$C$5:$G$5)+DCF!$G$6*(1+$B13)*(DCF!$H$8*(1-DCF!$H$10)+DCF!$H$13-DCF!$H$15)/(G$8-$B13)/(1+G$8)^DCF!$G$5+DCF!$B$29+DCF!$B$30)/'Dane historyczne'!$B$37,"-") -> 288.87482
A15: Aktualny kurs (USD) | B15: =Założenia!$B$20 -> 709.33
A16: Wartość bazowa (USD) | B16: =DCF!$B$33 -> 344.99273
A17: Kontrola: środek tabeli = wartość bazowa | B17: =IF(ABS(E11-B16)<0.01,"OK","BŁĄD") -> OK

Sheet Ledger
A1: META - ledger: wszystkie wpisy ze źródłem i cytatem
A3: id | B3: klasa | C3: klucz | D3: opis | E3: wartość | F3: jednostka | G3: okres | H3: źródło | I3: strona | J3: adres | K3: cytat / uzasadnienie
A4: F-01 | B4: fakt | C4: revenue_2025 | D4: Przychody ogółem | E4: 200966 | F4: mln USD | G4: 2025 | H4: Meta Platforms, Inc. - raport roczny 10-K za 2025 r. | I4: 89 | J4: https://www.sec.gov/Archives/edgar/data/1326801/000162828026003942/meta-20251231.htm | K4: Revenue $ 200,966 $ 164,501 $ 134,902
A5: F-02 | B5: fakt | C5: revenue_2024 | D5: Przychody ogółem | E5: 164501 | F5: mln USD | G5: 2024 | H5: Meta Platforms, Inc. - raport roczny 10-K za 2025 r. | I5: 89 | J5: https://www.sec.gov/Archives/edgar/data/1326801/000162828026003942/meta-20251231.htm | K5: Revenue $ 200,966 $ 164,501 $ 134,902
A6: F-03 | B6: fakt | C6: revenue_2023 | D6: Przychody ogółem | E6: 134902 | F6: mln USD | G6: 2023 | H6: Meta Platforms, Inc. - raport roczny 10-K za 2025 r. | I6: 89 | J6: https://www.sec.gov/Archives/edgar/data/1326801/000162828026003942/meta-20251231.htm | K6: Revenue $ 200,966 $ 164,501 $ 134,902
A7: F-04 | B7: fakt | C7: operating_income_2025 | D7: Zysk operacyjny | E7: 83276 | F7: mln USD | G7: 2025 | H7: Meta Platforms, Inc. - raport roczny 10-K za 2025 r. | I7: 89 | J7: https://www.sec.gov/Archives/edgar/data/1326801/000162828026003942/meta-20251231.htm | K7: Income from operations 83,276 69,380 46,751
A8: F-05 | B8: fakt | C8: operating_income_2024 | D8: Zysk operacyjny | E8: 69380 | F8: mln USD | G8: 2024 | H8: Meta Platforms, Inc. - raport roczny 10-K za 2025 r. | I8: 89 | J8: https://www.sec.gov/Archives/edgar/data/1326801/000162828026003942/meta-20251231.htm | K8: Income from operations 83,276 69,380 46,751
A9: F-06 | B9: fakt | C9: operating_income_2023 | D9: Zysk operacyjny | E9: 46751 | F9: mln USD | G9: 2023 | H9: Meta Platforms, Inc. - raport roczny 10-K za 2025 r. | I9: 89 | J9: https://www.sec.gov/Archives/edgar/data/1326801/000162828026003942/meta-20251231.htm | K9: Income from operations 83,276 69,380 46,751
A10: F-07 | B10: fakt | C10: net_income_2025 | D10: Zysk netto | E10: 60458 | F10: mln USD | G10: 2025 | H10: Meta Platforms, Inc. - raport roczny 10-K za 2025 r. | I10: 89 | J10: https://www.sec.gov/Archives/edgar/data/1326801/000162828026003942/meta-20251231.htm | K10: Net income $ 60,458 $ 62,360 $ 39,098
A11: F-08 | B11: fakt | C11: depreciation_amortization_2025 | D11: Amortyzacja (depreciation and amortization) | E11: 18616 | F11: mln USD | G11: 2025 | H11: Meta Platforms, Inc. - raport roczny 10-K za 2025 r. | I11: 92 | J11: https://www.sec.gov/Archives/edgar/data/1326801/000162828026003942/meta-20251231.htm | K11: Depreciation and amortization 18,616 15,498 11,178
A12: F-09 | B12: fakt | C12: capex_2025 | D12: Nakłady inwestycyjne - zakup rzeczowych aktywów trwałych (wypływ gotówki, w raporcie w nawiasie, stąd wartość ujemna) | E12: -69691 | F12: mln USD | G12: 2025 | H12: Meta Platforms, Inc. - raport roczny 10-K za 2025 r. | I12: 92 | J12: https://www.sec.gov/Archives/edgar/data/1326801/000162828026003942/meta-20251231.htm | K12: Purchases of property and equipment (69,691) (37,256) (27,045)
A13: F-10 | B13: fakt | C13: income_before_tax_2025 | D13: Zysk przed opodatkowaniem | E13: 85932 | F13: mln USD | G13: 2025 | H13: Meta Platforms, Inc. - raport roczny 10-K za 2025 r. | I13: 89 | J13: https://www.sec.gov/Archives/edgar/data/1326801/000162828026003942/meta-20251231.htm | K13: Income before provision for income taxes 85,932 70,663 47,428
A14: F-11 | B14: fakt | C14: income_tax_2025 | D14: Podatek dochodowy | E14: 25474 | F14: mln USD | G14: 2025 | H14: Meta Platforms, Inc. - raport roczny 10-K za 2025 r. | I14: 89 | J14: https://www.sec.gov/Archives/edgar/data/1326801/000162828026003942/meta-20251231.htm | K14: Provision for income taxes 25,474 8,303 8,330
A15: F-12 | B15: fakt | C15: cash_and_equivalents_2025 | D15: Gotówka i ekwiwalenty gotówki na koniec roku | E15: 35873 | F15: mln USD | G15: 2025-12-31 | H15: Meta Platforms, Inc. - raport roczny 10-K za 2025 r. | I15: 88 | J15: https://www.sec.gov/Archives/edgar/data/1326801/000162828026003942/meta-20251231.htm | K15: Cash and cash equivalents $ 35,873 $ 43,889
... A31: F-28 | B31: fakt | C31: family_daily_active_people_dec_2025 | D31: Dzienna liczba aktywnych osób we wszystkich aplikacjach (DAP), średnio w grudniu 2025 | E31: 3.58 | F31: mld osób | G31: 2025-12 | H31: Meta Platforms, Inc. - raport roczny 10-K za 2025 r. | I31: 61 | J31: https://www.sec.gov/Archives/edgar/data/1326801/000162828026003942/meta-20251231.htm | K31: Family daily active people (DAP) was 3.58 billion on average for December 2025, an increase of 7% year-over-year.
A32: F-29 | B32: fakt | C32: superintelligence_vision | D32: Cel w AI: budowa superinteligencji, czyli AI przewyższającej ludzką inteligencję | E32: superintelligence | F32: n/d | G32: 2025 | H32: Meta Platforms, Inc. - raport roczny 10-K za 2025 r. | I32: 6 | J32: https://www.sec.gov/Archives/edgar/data/1326801/000162828026003942/meta-20251231.htm | K32: We are also working to develop the next generation of AI models and advance our vision to build superintelligence, which we define as AI that surpasses human intelligence.
A33: F-30 | B33: fakt | C33: meta_ray_ban_display_launch | D33: Nowy produkt: okulary AI z wyświetlaczem w szkle, wprowadzone w 2025 r. | E33: Meta Ray-Ban Display | F33: n/d | G33: 2025 | H33: Meta Platforms, Inc. - raport roczny 10-K za 2025 r. | I33: 7 | J33: https://www.sec.gov/Archives/edgar/data/1326801/000162828026003942/meta-20251231.htm | K33: In 2025, we introduced Meta Ray-Ban Display, which combines our AI glasses with an integrated display built into the lens.
A34: F-31 | B34: fakt | C34: rl_wearables_opex_share_2026 | D34: Planowany udział urządzeń noszonych (wearables) w kosztach operacyjnych Reality Labs w 2026 r. | E34: 70 | F34: % | G34: 2026 | H34: Meta Platforms, Inc. - raport roczny 10-K za 2025 r. | I34: 7 | J34: https://www.sec.gov/Archives/edgar/data/1326801/000162828026003942/meta-20251231.htm | K34: In 2026, we expect to spend approximately 70% of our Reality Labs operating expenses on our wearables initiatives, and the remaining 30% on our VR and Horizon initiatives.
A35: F-32 | B35: fakt | C35: data_center_locations | D35: Liczba własnych lokalizacji centrów danych na świecie | E35: 30 | F35: szt. | G35: 2025 | H35: Meta Platforms, Inc. - raport roczny 10-K za 2025 r. | I35: 51 | J35: https://www.sec.gov/Archives/edgar/data/1326801/000162828026003942/meta-20251231.htm | K35: We own 30 data center locations globally and we also lease some data centers at selected locations.
A36: F-33 | B36: fakt | C36: capex_guidance_2026_low | D36: Plan nakładów inwestycyjnych na 2026 r. - dolna granica | E36: 115 | F36: mld USD | G36: 2026 | H36: Meta Platforms, Inc. - raport roczny 10-K za 2025 r. | I36: 77 | J36: https://www.sec.gov/Archives/edgar/data/1326801/000162828026003942/meta-20251231.htm | K36: We anticipate making capital expenditures of approximately $115 billion to $135 billion in 2026 to support our AI efforts and core business.
A37: F-34 | B37: fakt | C37: capex_guidance_2026_high | D37: Plan nakładów inwestycyjnych na 2026 r. - górna granica | E37: 135 | F37: mld USD | G37: 2026 | H37: Meta Platforms, Inc. - raport roczny 10-K za 2025 r. | I37: 77 | J37: https://www.sec.gov/Archives/edgar/data/1326801/000162828026003942/meta-20251231.htm | K37: We anticipate making capital expenditures of approximately $115 billion to $135 billion in 2026 to support our AI efforts and core business.
A38: F-35 | B38: fakt | C38: risk_advertising_dependence | D38: Ryzyko: niemal wszystkie przychody pochodzą z reklam; odejście reklamodawców lub cięcie ich wydatków mocno zaszkodzi spółce | E38: zależność od reklam | F38: n/d | G38: 2025 | H38: Meta Platforms, Inc. - raport roczny 10-K za 2025 r. | I38: 15 | J38: https://www.sec.gov/Archives/edgar/data/1326801/000162828026003942/meta-20251231.htm | K38: We generate substantially all of our revenue from advertising. The loss of marketers, or reduction in spending by marketers, could seriously harm our business.
A39: F-36 | B39: fakt | C39: risk_ai_investments | D39: Ryzyko: duże inwestycje, zwłaszcza w AI i Reality Labs, obniżają marżę operacyjną i rentowność; jeśli w dłuższym terminie się nie powiodą, ucierpią biznes i wyniki finansowe | E39: inwestycje w AI | F39: n/d | G39: 2025 | H39: Meta Platforms, Inc. - raport roczny 10-K za 2025 r. | I39: 26 | J39: https://www.sec.gov/Archives/edgar/data/1326801/000162828026003942/meta-20251231.htm | K39: We incur significant expenses in operating our business, and some of our investments, particularly our investments in our artificial intelligence initiatives as well as Reality Labs, have the effect of reducing our operating margin and profitability. If our investments are not successful longer-term, our business and financial performance will be harmed.
A40: F-37 | B40: fakt | C40: risk_regulation | D40: Ryzyko: złożone i zmieniające się przepisy w USA i za granicą (prywatność, dane, konkurencja, AI) | E40: regulacje | F40: n/d | G40: 2025 | H40: Meta Platforms, Inc. - raport roczny 10-K za 2025 r. | I40: 12 | J40: https://www.sec.gov/Archives/edgar/data/1326801/000162828026003942/meta-20251231.htm | K40: complex and evolving U.S. and foreign privacy, data use, data combination, data protection, content and content moderation, competition, youth, safety, consumer protection, advertising, and other laws and regulations, including the General Data Protection Regulation (GDPR), Digital Markets Act (DMA), Digital Services Act (DSA), UK Online Safety Act (OSA), Artificial Intelligence Act (EU AI Act), and the UK Digital Markets, Competition and Consumer Act (DMCC);
A41: R-01 | B41: dana_rynkowa | C41: share_price | D41: Kurs zamknięcia akcji META (Nasdaq), ostatnia sesja; zaokrąglony do centów | E41: 709.33 | F41: USD | G41: 2026-10-16 | H41: Yahoo Finance - chart API (odpowiedź JSON) | I41: n/d (www) | J41: https://query1.finance.yahoo.com/v8/finance/chart/META?range=5d&interval=1d | K41: "close": [ 742.9600219726562, 762.5, 737.5399780273438, 736.719970703125, 709.3300170898438 ]
A42: R-02 | B42: dana_rynkowa | C42: us_treasury_10y_yield | D42: Rentowność 10-letnich obligacji skarbowych USA (seria DGS10) | E42: 5.1 | F42: % | G42: 2026-10-15 | H42: FRED, Federal Reserve Bank of St. Louis - seria DGS10 (CSV) | I42: n/d (www) | J42: https://fred.stlouisfed.org/graph/fredgraph.csv?id=DGS10 | K42: 2026-10-15,5.10
A43: Z-01 | B43: zalozenie | C43: revenue_growth_2026 | D43: Wzrost przychodów r/r w 2026 r. | E43: 18 | F43: % | G43: 2026 | K43: Przychody rosły o ok. 22% w 2025 r. (F-02 -> F-01) i ok. 22% w 2024 r. (F-03 -> F-02). Zakładamy lekkie spowolnienie przy tak dużej skali, a liczba użytkowników (F-28) rosła już tylko o 7%.
A44: Z-02 | B44: zalozenie | C44: revenue_growth_2027 | D44: Wzrost przychodów r/r w 2027 r. | E44: 15 | F44: % | G44: 2027 | K44: Dalsze stopniowe spowolnienie: przychody prawie w całości pochodzą z reklam (F-35), a rynek reklamy rośnie wolniej niż Meta w ostatnich latach.
A45: Z-03 | B45: zalozenie | C45: revenue_growth_2028 | D45: Wzrost przychodów r/r w 2028 r. | E45: 12 | F45: % | G45: 2028 | K45: Wzrost dalej słabnie wraz ze skalą biznesu; zakładamy, że AI wspiera skuteczność reklam, ale nie odwraca trendu spowolnienia.
A46: Z-04 | B46: zalozenie | C46: revenue_growth_2029 | D46: Wzrost przychodów r/r w 2029 r. | E46: 10 | F46: % | G46: 2029 | K46: Kontynuacja łagodnego spowolnienia w stronę dojrzałej spółki.
A47: Z-05 | B47: zalozenie | C47: revenue_growth_2030 | D47: Wzrost przychodów r/r w 2030 r. | E47: 8 | F47: % | G47: 2030 | K47: Ostatni rok prognozy; wzrost zbliża się do poziomu, z którego da się przejść do okresu rezydualnego (Z-25).
A48: Z-06 | B48: zalozenie | C48: operating_margin_2026 | D48: Marża operacyjna w 2026 r. | E48: 38 | F48: % | G48: 2026 | K48: Marża operacyjna w 2025 r. wyniosła 41% (F-27). Rekordowe nakłady (F-33, F-34) podnoszą amortyzację (Z-17 do Z-21), która obniża zysk operacyjny; do tego strata Reality Labs (F-21). Zakładamy marżę przed amortyzacją ok. 50-52% minus rosnąca amortyzacja.
A49: Z-07 | B49: zalozenie | C49: operating_margin_2027 | D49: Marża operacyjna w 2027 r. | E49: 37 | F49: % | G49: 2027 | K49: Marża operacyjna w 2025 r. wyniosła 41% (F-27). Rekordowe nakłady (F-33, F-34) podnoszą amortyzację (Z-17 do Z-21), która obniża zysk operacyjny; do tego strata Reality Labs (F-21). Zakładamy marżę przed amortyzacją ok. 50-52% minus rosnąca amortyzacja.
A50: Z-08 | B50: zalozenie | C50: operating_margin_2028 | D50: Marża operacyjna w 2028 r. | E50: 36 | F50: % | G50: 2028 | K50: Marża operacyjna w 2025 r. wyniosła 41% (F-27). Rekordowe nakłady (F-33, F-34) podnoszą amortyzację (Z-17 do Z-21), która obniża zysk operacyjny; do tego strata Reality Labs (F-21). Zakładamy marżę przed amortyzacją ok. 50-52% minus rosnąca amortyzacja.
A51: Z-09 | B51: zalozenie | C51: operating_margin_2029 | D51: Marża operacyjna w 2029 r. | E51: 36 | F51: % | G51: 2029 | K51: Marża operacyjna w 2025 r. wyniosła 41% (F-27). Rekordowe nakłady (F-33, F-34) podnoszą amortyzację (Z-17 do Z-21), która obniża zysk operacyjny; do tego strata Reality Labs (F-21). Zakładamy marżę przed amortyzacją ok. 50-52% minus rosnąca amortyzacja.
A52: Z-10 | B52: zalozenie | C52: operating_margin_2030 | D52: Marża operacyjna w 2030 r. | E52: 36 | F52: % | G52: 2030 | K52: Marża operacyjna w 2025 r. wyniosła 41% (F-27). Rekordowe nakłady (F-33, F-34) podnoszą amortyzację (Z-17 do Z-21), która obniża zysk operacyjny; do tego strata Reality Labs (F-21). Zakładamy marżę przed amortyzacją ok. 50-52% minus rosnąca amortyzacja.
A53: Z-11 | B53: zalozenie | C53: operating_margin_terminal | D53: Marża operacyjna w okresie rezydualnym (po 2030 r.) | E53: 36 | F53: % | G53: po 2030 | K53: Zakładamy, że marża z 2030 r. (Z-10) utrzymuje się, bo amortyzacja w okresie rezydualnym (Z-27) jest taka sama jak w 2030 r.
A54: Z-12 | B54: zalozenie | C54: capex_pct_revenue_2026 | D54: Nakłady inwestycyjne jako % przychodów w 2026 r. | E54: 52 | F54: % | G54: 2026 | K54: Spółka planuje 115-135 mld USD nakładów w 2026 r. (F-33, F-34); 52% prognozowanych przychodów to ok. 123 mld USD, czyli środek tego przedziału. W 2025 r. nakłady wyniosły ok. 35% przychodów (F-09, F-01).
... A69: Z-27 | B69: zalozenie | C69: da_pct_revenue_terminal | D69: Amortyzacja jako % przychodów w okresie rezydualnym | E69: 16 | F69: % | G69: po 2030 | K69: Pozostaje na poziomie z 2030 r. (Z-21): majątek zbudowany w latach 2026-2030 dalej się amortyzuje, a nakłady (Z-26) są tylko trochę wyższe niż amortyzacja.
A70: G-01 | B70: grafika | C70: photo_ai_glasses | D70: Okulary AI Ray-Ban Meta (1. generacja) z etui ładującym | E70: META/zrodla/grafiki/ray-ban-meta-gen-1-smart-glasses-with-charging-case.jpg | H70: Wikimedia Commons | J70: https://commons.wikimedia.org/wiki/File:Ray-Ban_Meta_Gen_1_smart_glasses_with_charging_case.jpg | K70: autor: CCadio; licencja: CC BY 4.0
...
