Workbook

Sheet Podsumowanie
A1: GOOG - wycena metodą DCF
A2: Wszystkie liczby w tym arkuszu to formuły odwołujące się do pozostałych arkuszy.
A4: Wynik | B4: Wartość
A5: Wartość jednej akcji z DCF (USD) | B5: =DCF!$B$33 -> 110.59103
A6: Aktualny kurs (USD) | B6: =Założenia!$B$20 -> 336.91
A7: Różnica: wartość z DCF wobec kursu | B7: =B5/B6-1 -> -0.67174903
A8: WACC | B8: =Założenia!$B$29 -> 0.106
A9: Wzrost w okresie rezydualnym | B9: =Założenia!$B$18 -> 0.03
A10: Wartość firmy (mln USD) | B10: =DCF!$B$28 -> 1257523.7
A11: Wartość kapitału własnego (mln USD) | B11: =DCF!$B$31 -> 1337819.7
A12: Udział wartości rezydualnej w wartości firmy | B12: =DCF!$B$34 -> 0.88872991
A14: Kluczowe założenia | B14: Wartość
A15: Wzrost przychodów 2026 | B15: =Założenia!$B$5 -> 0.14
A16: Wzrost przychodów 2030 | B16: =Założenia!$F$5 -> 0.06
A17: Marża operacyjna 2026 | B17: =Założenia!$B$7 -> 0.31
A18: Marża operacyjna po 2030 | B18: =Założenia!$G$7 -> 0.29
A19: Nakłady inwestycyjne / przychody 2026 | B19: =Założenia!$B$9 -> 0.35
A20: Nakłady inwestycyjne / przychody po 2030 | B20: =Założenia!$G$9 -> 0.14
A21: Amortyzacja / przychody po 2030 | B21: =Założenia!$G$11 -> 0.11
A22: Stopa podatkowa | B22: =Założenia!$B$15 -> 0.17
A23: Stopa wolna od ryzyka (10Y UST) | B23: =Założenia!$B$19 -> 0.051
A24: Beta | B24: =Założenia!$B$16 -> 1.1
A25: Premia za ryzyko rynkowe | B25: =Założenia!$B$17 -> 0.05
D27: Dane do wykresów
D28: Rok | E28: Przychody (mln USD) | F28: Marża operacyjna | G28: FCF (mln USD)
D29: 2023 | E29: ='Dane historyczne'!$B$5 -> 307394 | F29: ='Dane historyczne'!$B$7 -> 0.2742181
D30: 2024 | E30: ='Dane historyczne'!$C$5 -> 350018 | F30: ='Dane historyczne'!$C$7 -> 0.32109777
D31: 2025 | E31: ='Dane historyczne'!$D$5 -> 402836 | F31: ='Dane historyczne'!$D$7 -> 0.32032639
D32: 2026 | E32: =DCF!$C$6 -> 459233.04 | F32: =DCF!$C$8 -> 0.31 | G32: =DCF!$C$17 -> -10424.59
D33: 2027 | E33: =DCF!$D$6 -> 514341 | F33: =DCF!$D$8 -> 0.3 | G33: =DCF!$D$17 -> 4629.069
D34: 2028 | E34: =DCF!$E$6 -> 565775.11 | F34: =DCF!$E$8 -> 0.29 | G34: =DCF!$E$17 -> 34342.549
D35: 2029 | E35: =DCF!$F$6 -> 611037.11 | F35: =DCF!$F$8 -> 0.29 | G35: =DCF!$F$17 -> 79862.551
D36: 2030 | E36: =DCF!$G$6 -> 647699.34 | F36: =DCF!$G$8 -> 0.29 | G36: =DCF!$G$17 -> 110562.28
D39: Od wartości firmy do kapitału | E39: Podstawa (pomocnicza) | F39: Wartość (mln USD)
D40: PV FCF 2026-2030 | E40: =0 -> 0 | F40: =DCF!$B$22 -> 139924.78
D41: PV wartości rezydualnej | E41: =MIN(0,DCF!$B$22)+MAX(0,DCF!$B$22) -> 139924.78 | F41: =DCF!$B$27 -> 1117599
D42: Wartość firmy | E42: =0 -> 0 | F42: =DCF!$B$28 -> 1257523.7
D43: + Gotówka i papiery | E43: =DCF!$B$28 -> 1257523.7 | F43: =DCF!$B$29 -> 126843
D44: - Dług | E44: =DCF!$B$28+DCF!$B$29+DCF!$B$30 -> 1337819.7 | F44: =-DCF!$B$30 -> 46547
D45: Kapitał własny | E45: =0 -> 0 | F45: =DCF!$B$31 -> 1337819.7
...

Sheet Dane historyczne
A1: GOOG - dane historyczne z raportu 10-K (mln USD, jeśli nie podano inaczej)
A2: Niebieskie liczby pochodzą z ledgera; obok id wpisu, w komentarzu komórki cytat i strona źródła.
A4: Pozycja | B4: 2023 | C4: 2024 | D4: 2025 | E4: id 2023 | F4: id 2024 | G4: id 2025
A5: Przychody | B5: 307394 | C5: 350018 | D5: 402836 | E5: F-03 | F5: F-02 | G5: F-01
A6: Zysk operacyjny | B6: 84293 | C6: 112390 | D6: 129039 | E6: F-06 | F6: F-05 | G6: F-04
A7: Marża operacyjna | B7: =IF(B5=0,0,B6/B5) -> 0.2742181 | C7: =IF(C5=0,0,C6/C5) -> 0.32109777 | D7: =IF(D5=0,0,D6/D5) -> 0.32032639
A8: Wzrost przychodów r/r | C8: =IF(B5=0,0,C5/B5-1) -> 0.13866243 | D8: =IF(C5=0,0,D5/C5-1) -> 0.15090081
A10: Pozostałe fakty | B10: Wartość | C10: Jednostka | D10: Okres | E10: id
A11: Zysk netto (Net income) | B11: 132170 | C11: mln USD | D11: 2025 | E11: F-07
A12: Amortyzacja rzeczowych aktywów trwałych (Depreciation of property and equipment), rachunek przepływów | B12: 21136 | C12: mln USD | D12: 2025 | E12: F-08
A13: Nakłady inwestycyjne (Purchases of property and equipment), wypływ gotówki | B13: -91447 | C13: mln USD | D13: 2025 | E13: F-09
A14: Zysk przed opodatkowaniem (Income before income taxes) | B14: 158826 | C14: mln USD | D14: 2025 | E14: F-10
A15: Podatek dochodowy (Provision for income taxes) | B15: 26656 | C15: mln USD | D15: 2025 | E15: F-11
A16: Gotówka i ekwiwalenty (Cash and cash equivalents) na koniec roku | B16: 30708 | C16: mln USD | D16: 2025-12-31 | E16: F-12
A17: Papiery wartościowe (Marketable securities) na koniec roku | B17: 96135 | C17: mln USD | D17: 2025-12-31 | E17: F-13
A18: Dług długoterminowy (Long-term debt) na koniec roku | B18: 46547 | C18: mln USD | D18: 2025-12-31 | E18: F-14
A19: Rzeczowe aktywa trwałe netto (Property and equipment, net) na koniec roku | B19: 246597 | C19: mln USD | D19: 2025-12-31 | E19: F-15
A20: Rzeczowe aktywa trwałe netto (Property and equipment, net) na koniec roku | B20: 171036 | C20: mln USD | D20: 2024-12-31 | E20: F-16
A21: Efektywna stopa podatkowa (Effective tax rate) | B21: 0.168 | C21: ułamek (%) | D21: 2025 | E21: F-17
A22: Efektywna stopa podatkowa (Effective tax rate) | B22: 0.164 | C22: ułamek (%) | D22: 2024 | E22: F-18
... A38: Liczba pracowników na koniec roku | B38: 190820 | C38: osób | D38: 2025-12-31 | E38: F-38
A40: Wielkości wyliczone | B40: Wartość | C40: Jednostka | D40: Okres | E40: Formuła
A41: Gotówka i papiery wartościowe | B41: ='Dane historyczne'!$B$16+'Dane historyczne'!$B$17 -> 126843 | C41: mln USD | D41: 2025-12-31 | E41: F-12 + F-13
A42: Dług (długoterminowy, plus krótkoterminowy, jeśli jest w ledgerze) | B42: ='Dane historyczne'!$B$18 -> 46547 | C42: mln USD | D42: 2025-12-31 | E42: F-14
A43: Liczba akcji wszystkich klas | B43: ='Dane historyczne'!$B$23+'Dane historyczne'!$B$24+'Dane historyczne'!$B$25 -> 12097 | C43: mln szt. | D43: 2026-01-28 | E43: (F-19 + F-20 + F-21), w mln szt.
A44: Nakłady inwestycyjne / przychody | B44: =ABS('Dane historyczne'!$B$13)/'Dane historyczne'!$D$5 -> 0.22700801 | C44: % | D44: 2025 | E44: |F-09| / F-01
A45: Amortyzacja / przychody | B45: =('Dane historyczne'!$B$12)/'Dane historyczne'!$D$5 -> 0.052468002 | C45: % | D45: 2025 | E45: (F-08) / F-01
A46: Efektywna stopa podatkowa (wyliczona) | B46: =IF('Dane historyczne'!$B$14=0,0,'Dane historyczne'!$B$15/'Dane historyczne'!$B$14) -> 0.16783146 | C46: % | D46: 2025 | E46: F-11 / F-10

Sheet Założenia
A1: GOOG - założenia modelu DCF
A2: Niebieskie komórki to założenia z ledgera (Z-..) i dane rynkowe (R-..). Zmiana wartości przelicza cały model. Uzasadnienie w komentarzu komórki i w tabeli poniżej.
A4: Prognoza | B4: 2026 | C4: 2027 | D4: 2028 | E4: 2029 | F4: 2030 | G4: Po 2030
A5: Wzrost przychodów r/r | B5: 0.14 | C5: 0.12 | D5: 0.1 | E5: 0.08 | F5: 0.06
A6: id wpisu | B6: Z-01 | C6: Z-02 | D6: Z-03 | E6: Z-04 | F6: Z-05
A7: Marża operacyjna | B7: 0.31 | C7: 0.3 | D7: 0.29 | E7: 0.29 | F7: 0.29 | G7: 0.29
A8: id wpisu | B8: Z-06 | C8: Z-07 | D8: Z-08 | E8: Z-09 | F8: Z-10 | G8: Z-11
A9: Nakłady inwestycyjne / przychody | B9: 0.35 | C9: 0.33 | D9: 0.28 | E9: 0.22 | F9: 0.18 | G9: 0.14
A10: id wpisu | B10: Z-12 | C10: Z-13 | D10: Z-14 | E10: Z-15 | F10: Z-16 | G10: Z-26
A11: Amortyzacja / przychody | B11: 0.07 | C11: 0.09 | D11: 0.1 | E11: 0.11 | F11: 0.11 | G11: 0.11
A12: id wpisu | B12: Z-17 | C12: Z-18 | D12: Z-19 | E12: Z-20 | F12: Z-21 | G12: Z-27
A14: Pozostałe założenia i dane rynkowe | B14: Wartość | C14: id | D14: Uwagi
A15: Stopa podatkowa do modelu DCF | B15: 0.17 | C15: Z-22 | D15: założenie
A16: Beta akcji Alphabet | B16: 1.1 | C16: Z-23 | D16: założenie
A17: Premia za ryzyko rynkowe (USA) | B17: 0.05 | C17: Z-24 | D17: założenie
A18: Wzrost w okresie rezydualnym (po 2030 r.) | B18: 0.03 | C18: Z-25 | D18: założenie
A19: Rentowność 10-letnich obligacji skarbowych USA (seria DGS10) | B19: 0.051 | C19: R-02 | D19: stan na 2026-10-15, pobrano 2026-10-17
A20: Kurs zamknięcia akcji GOOG (klasa C, Nasdaq), ostatnia sesja; zaokrąglony do centów | B20: 336.91 | C20: R-01 | D20: stan na 2026-10-16, pobrano 2026-10-17
A22: Koszt kapitału (WACC) | B22: Wartość | D22: Formuła
A23: Koszt kapitału własnego (CAPM) | B23: =Założenia!$B$19+Założenia!$B$16*Założenia!$B$17 -> 0.106 | D23: stopa wolna od ryzyka + beta × premia za ryzyko
A24: Dług (mln USD) | B24: ='Dane historyczne'!$B$42 -> 46547 | D24: z arkusza 'Dane historyczne'
A25: Kapitalizacja rynkowa (mln USD) | B25: =Założenia!$B$20*'Dane historyczne'!$B$43 -> 4075600.3 | D25: kurs × liczba akcji
A26: Udział długu w finansowaniu D/(D+E) | B26: =Założenia!$B$24/(Założenia!$B$24+Założenia!$B$25) -> 0.01129193 | D26: dług / (dług + kapitalizacja)
A27: Próg istotności długu (parametr modelu) | B27: 0.1 | D27: powyżej progu dług trzeba ująć w WACC
A28: Czy dług jest istotny? | B28: =IF(Założenia!$B$26>Założenia!$B$27,"TAK - dodaj koszt długu do WACC","NIE - WACC = koszt kapitału własnego") -> NIE - WACC = koszt kapitału własnego
A29: WACC | B29: =Założenia!$B$23 -> 0.106 | D29: równy kosztowi kapitału własnego, bo dług jest poniżej progu istotności
A31: Założenie | B31: id | C31: Uzasadnienie
A32: Wzrost przychodów r/r w 2026 r. | B32: Z-01 | C32: Przychody rosły o ok. 14% w 2024 r. (F-03 -> F-02) i ok. 15% w 2025 r. (F-02 -> F-01). Zakładamy podobne tempo w 2026 r., wspierane przez szybko rosnący Google Cloud (F-28 -> F-23) i duży portfel zamówień (F-32).
A33: Wzrost przychodów r/r w 2027 r. | B33: Z-02 | C33: Stopniowe spowolnienie: ponad 70% przychodów to reklama online (F-37), a ten rynek rośnie wolniej niż chmura.
A34: Wzrost przychodów r/r w 2028 r. | B34: Z-03 | C34: Wzrost dalej słabnie wraz ze skalą biznesu; Google Cloud (F-23) rośnie szybciej, ale jest wciąż znacznie mniejszy niż Google Services (F-22).
A35: Wzrost przychodów r/r w 2029 r. | B35: Z-04 | C35: Kontynuacja łagodnego spowolnienia w stronę dojrzałej spółki.
A36: Wzrost przychodów r/r w 2030 r. | B36: Z-05 | C36: Ostatni rok prognozy; wzrost zbliża się do poziomu, z którego da się przejść do okresu rezydualnego (Z-25).
A37: Marża operacyjna w 2026 r. | B37: Z-06 | C37: Marża operacyjna wyniosła ok. 32% w 2024 i 2025 r. (F-05/F-02, F-04/F-01), przy amortyzacji ok. 5% przychodów (F-08). Rosnąca amortyzacja (Z-17 do Z-21) obniża marżę o kilka punktów, częściowo równoważy to rosnąca rentowność Google Cloud (F-26) i mniejsza strata Other Bets niż w 2025 r. (F-27).
A38: Marża operacyjna w 2027 r. | B38: Z-07 | C38: Marża operacyjna wyniosła ok. 32% w 2024 i 2025 r. (F-05/F-02, F-04/F-01), przy amortyzacji ok. 5% przychodów (F-08). Rosnąca amortyzacja (Z-17 do Z-21) obniża marżę o kilka punktów, częściowo równoważy to rosnąca rentowność Google Cloud (F-26) i mniejsza strata Other Bets niż w 2025 r. (F-27).
A39: Marża operacyjna w 2028 r. | B39: Z-08 | C39: Marża operacyjna wyniosła ok. 32% w 2024 i 2025 r. (F-05/F-02, F-04/F-01), przy amortyzacji ok. 5% przychodów (F-08). Rosnąca amortyzacja (Z-17 do Z-21) obniża marżę o kilka punktów, częściowo równoważy to rosnąca rentowność Google Cloud (F-26) i mniejsza strata Other Bets niż w 2025 r. (F-27).
A40: Marża operacyjna w 2029 r. | B40: Z-09 | C40: Marża operacyjna wyniosła ok. 32% w 2024 i 2025 r. (F-05/F-02, F-04/F-01), przy amortyzacji ok. 5% przychodów (F-08). Rosnąca amortyzacja (Z-17 do Z-21) obniża marżę o kilka punktów, częściowo równoważy to rosnąca rentowność Google Cloud (F-26) i mniejsza strata Other Bets niż w 2025 r. (F-27).
A41: Marża operacyjna w 2030 r. | B41: Z-10 | C41: Marża operacyjna wyniosła ok. 32% w 2024 i 2025 r. (F-05/F-02, F-04/F-01), przy amortyzacji ok. 5% przychodów (F-08). Rosnąca amortyzacja (Z-17 do Z-21) obniża marżę o kilka punktów, częściowo równoważy to rosnąca rentowność Google Cloud (F-26) i mniejsza strata Other Bets niż w 2025 r. (F-27).
A42: Marża operacyjna w okresie rezydualnym (po 2030 r.) | B42: Z-11 | C42: Zakładamy, że marża z 2030 r. (Z-10) utrzymuje się, bo amortyzacja w okresie rezydualnym (Z-27) jest taka sama jak w 2030 r.
... A58: Amortyzacja jako % przychodów w okresie rezydualnym | B58: Z-27 | C58: Pozostaje na poziomie z 2030 r. (Z-21): majątek zbudowany w latach 2026-2030 dalej się amortyzuje, a nakłady (Z-26) są tylko trochę wyższe niż amortyzacja.

Sheet DCF
A1: GOOG - model DCF (mln USD)
A2: Wszystkie komórki to formuły. Dane wejściowe są w arkuszach 'Założenia' i 'Dane historyczne'. Przepływy dyskontowane na koniec każdego roku od końca 2025 r.
A4: Pozycja | B4: 2025 (raport) | C4: 2026 P | D4: 2027 P | E4: 2028 P | F4: 2029 P | G4: 2030 P | H4: Rezydualny (2031)
A5: Okres dyskontowy t (lata) | C5: =1 -> 1 | D5: =C5+1 -> 2 | E5: =D5+1 -> 3 | F5: =E5+1 -> 4 | G5: =F5+1 -> 5
A6: Przychody | B6: ='Dane historyczne'!$D$5 -> 402836 | C6: =B6*(1+C7) -> 459233.04 | D6: =C6*(1+D7) -> 514341 | E6: =D6*(1+E7) -> 565775.11 | F6: =E6*(1+F7) -> 611037.11 | G6: =F6*(1+G7) -> 647699.34 | H6: =G6*(1+H7) -> 667130.32
A7: Wzrost r/r | C7: =Założenia!$B$5 -> 0.14 | D7: =Założenia!$C$5 -> 0.12 | E7: =Założenia!$D$5 -> 0.1 | F7: =Założenia!$E$5 -> 0.08 | G7: =Założenia!$F$5 -> 0.06 | H7: =Założenia!$B$18 -> 0.03
A8: Marża operacyjna | C8: =Założenia!$B$7 -> 0.31 | D8: =Założenia!$C$7 -> 0.3 | E8: =Założenia!$D$7 -> 0.29 | F8: =Założenia!$E$7 -> 0.29 | G8: =Założenia!$F$7 -> 0.29 | H8: =Założenia!$G$7 -> 0.29
A9: Zysk operacyjny (EBIT) | C9: =C6*C8 -> 142362.24 | D9: =D6*D8 -> 154302.3 | E9: =E6*E8 -> 164074.78 | F9: =F6*F8 -> 177200.76 | G9: =G6*G8 -> 187832.81 | H9: =H6*H8 -> 193467.79
A10: Stopa podatkowa | C10: =Założenia!$B$15 -> 0.17 | D10: =Założenia!$B$15 -> 0.17 | E10: =Założenia!$B$15 -> 0.17 | F10: =Założenia!$B$15 -> 0.17 | G10: =Założenia!$B$15 -> 0.17 | H10: =Założenia!$B$15 -> 0.17
A11: Podatek | C11: =-C9*C10 -> -24201.581 | D11: =-D9*D10 -> -26231.391 | E11: =-E9*E10 -> -27892.713 | F11: =-F9*F10 -> -30124.13 | G11: =-G9*G10 -> -31931.577 | H11: =-H9*H10 -> -32889.525
A12: NOPAT | C12: =C9+C11 -> 118160.66 | D12: =D9+D11 -> 128070.91 | E12: =E9+E11 -> 136182.07 | F12: =F9+F11 -> 147076.63 | G12: =G9+G11 -> 155901.23 | H12: =H9+H11 -> 160578.27
A13: Amortyzacja / przychody | C13: =Założenia!$B$11 -> 0.07 | D13: =Założenia!$C$11 -> 0.09 | E13: =Założenia!$D$11 -> 0.1 | F13: =Założenia!$E$11 -> 0.11 | G13: =Założenia!$F$11 -> 0.11 | H13: =Założenia!$G$11 -> 0.11
A14: Amortyzacja | C14: =C6*C13 -> 32146.313 | D14: =D6*D13 -> 46290.69 | E14: =E6*E13 -> 56577.511 | F14: =F6*F13 -> 67214.083 | G14: =G6*G13 -> 71246.927 | H14: =H6*H13 -> 73384.335
A15: Nakłady inwestycyjne / przychody | C15: =Założenia!$B$9 -> 0.35 | D15: =Założenia!$C$9 -> 0.33 | E15: =Założenia!$D$9 -> 0.28 | F15: =Założenia!$E$9 -> 0.22 | G15: =Założenia!$F$9 -> 0.18 | H15: =Założenia!$G$9 -> 0.14
A16: Nakłady inwestycyjne | C16: =-C6*C15 -> -160731.56 | D16: =-D6*D15 -> -169732.53 | E16: =-E6*E15 -> -158417.03 | F16: =-F6*F15 -> -134428.17 | G16: =-G6*G15 -> -116585.88 | H16: =-H6*H15 -> -93398.245
A17: Wolne przepływy pieniężne (FCF) | C17: =C12+C14+C16 -> -10424.59 | D17: =D12+D14+D16 -> 4629.069 | E17: =E12+E14+E16 -> 34342.549 | F17: =F12+F14+F16 -> 79862.551 | G17: =G12+G14+G16 -> 110562.28 | H17: =H12+H14+H16 -> 140564.36
A18: Czynnik dyskontowy | C18: =1/(1+$B$24)^C5 -> 0.90415913 | D18: =1/(1+$B$24)^D5 -> 0.81750374 | E18: =1/(1+$B$24)^E5 -> 0.73915347 | F18: =1/(1+$B$24)^F5 -> 0.66831236 | G18: =1/(1+$B$24)^G5 -> 0.60426072
A19: Wartość bieżąca FCF | C19: =C17*C18 -> -9425.4883 | D19: =D17*D18 -> 3784.2812 | E19: =E17*E18 -> 25384.414 | F19: =F17*F18 -> 53373.13 | G19: =G17*G18 -> 66808.442
A21: Wycena | B21: Wartość
A22: Suma wartości bieżących FCF 2026-2030 | B22: =SUM(C19:G19) -> 139924.78
A23: FCF okresu rezydualnego (rok 2031) | B23: =H17 -> 140564.36
A24: WACC | B24: =Założenia!$B$29 -> 0.106
A25: Wzrost w okresie rezydualnym (g) | B25: =Założenia!$B$18 -> 0.03
A26: Wartość rezydualna na koniec 2030 (Gordon: FCF 2031 / (WACC - g)) | B26: =IF(B24>B25,B23/(B24-B25),"WACC musi być większy od g") -> 1849531
A27: Wartość bieżąca wartości rezydualnej | B27: =B26*G18 -> 1117599
A28: Wartość firmy (EV) | B28: =B22+B27 -> 1257523.7
A29: + Gotówka i papiery wartościowe | B29: ='Dane historyczne'!$B$41 -> 126843
A30: - Dług | B30: =-'Dane historyczne'!$B$42 -> -46547
A31: Wartość kapitału własnego | B31: =B28+B29+B30 -> 1337819.7
A32: Liczba akcji wszystkich klas (mln) | B32: ='Dane historyczne'!$B$43 -> 12097
A33: Wartość jednej akcji (USD) | B33: =B31/B32 -> 110.59103
A34: Udział wartości rezydualnej w wartości firmy | B34: =B27/B28 -> 0.88872991

Sheet Wrażliwość
A1: GOOG - wartość jednej akcji (USD) przy różnych WACC i wzroście rezydualnym
A2: Każda komórka liczy pełną wycenę formułą: przepływy 2026-2030 z arkusza DCF, wartość rezydualna dla danego g i WACC, gotówka, dług, liczba akcji. Środek tabeli = wariant bazowy.
A4: Krok WACC (parametr) | B4: 0.01
A5: Krok g (parametr) | B5: 0.005
C7: WACC →
A8: g ↓ | C8: =Założenia!$B$29+(-2)*$B$4 -> 0.086 | D8: =Założenia!$B$29+(-1)*$B$4 -> 0.096 | E8: =Założenia!$B$29+(0)*$B$4 -> 0.106 | F8: =Założenia!$B$29+(1)*$B$4 -> 0.116 | G8: =Założenia!$B$29+(2)*$B$4 -> 0.126
B9: =Założenia!$B$18+(-2)*$B$5 -> 0.02 | C9: =IF(C$8>$B9,(SUMPRODUCT(DCF!$C$17:$G$17/(1+C$8)^DCF!$C$5:$G$5)+DCF!$G$6*(1+$B9)*(DCF!$H$8*(1-DCF!$H$10)+DCF!$H$13-DCF!$H$15)/(C$8-$B9)/(1+C$8)^DCF!$G$5+DCF!$B$29+DCF!$B$30)/'Dane historyczne'!$B$43,"-") -> 134.59803 | D9: =IF(D$8>$B9,(SUMPRODUCT(DCF!$C$17:$G$17/(1+D$8)^DCF!$C$5:$G$5)+DCF!$G$6*(1+$B9)*(DCF!$H$8*(1-DCF!$H$10)+DCF!$H$13-DCF!$H$15)/(D$8-$B9)/(1+D$8)^DCF!$G$5+DCF!$B$29+DCF!$B$30)/'Dane historyczne'!$B$43,"-") -> 114.42115 | E9: =IF(E$8>$B9,(SUMPRODUCT(DCF!$C$17:$G$17/(1+E$8)^DCF!$C$5:$G$5)+DCF!$G$6*(1+$B9)*(DCF!$H$8*(1-DCF!$H$10)+DCF!$H$13-DCF!$H$15)/(E$8-$B9)/(1+E$8)^DCF!$G$5+DCF!$B$29+DCF!$B$30)/'Dane historyczne'!$B$43,"-") -> 99.055764 | F9: =IF(F$8>$B9,(SUMPRODUCT(DCF!$C$17:$G$17/(1+F$8)^DCF!$C$5:$G$5)+DCF!$G$6*(1+$B9)*(DCF!$H$8*(1-DCF!$H$10)+DCF!$H$13-DCF!$H$15)/(F$8-$B9)/(1+F$8)^DCF!$G$5+DCF!$B$29+DCF!$B$30)/'Dane historyczne'!$B$43,"-") -> 86.992796 | G9: =IF(G$8>$B9,(SUMPRODUCT(DCF!$C$17:$G$17/(1+G$8)^DCF!$C$5:$G$5)+DCF!$G$6*(1+$B9)*(DCF!$H$8*(1-DCF!$H$10)+DCF!$H$13-DCF!$H$15)/(G$8-$B9)/(1+G$8)^DCF!$G$5+DCF!$B$29+DCF!$B$30)/'Dane historyczne'!$B$43,"-") -> 77.29294
B10: =Założenia!$B$18+(-1)*$B$5 -> 0.025 | C10: =IF(C$8>$B10,(SUMPRODUCT(DCF!$C$17:$G$17/(1+C$8)^DCF!$C$5:$G$5)+DCF!$G$6*(1+$B10)*(DCF!$H$8*(1-DCF!$H$10)+DCF!$H$13-DCF!$H$15)/(C$8-$B10)/(1+C$8)^DCF!$G$5+DCF!$B$29+DCF!$B$30)/'Dane historyczne'!$B$43,"-") -> 144.67053 | D10: =IF(D$8>$B10,(SUMPRODUCT(DCF!$C$17:$G$17/(1+D$8)^DCF!$C$5:$G$5)+DCF!$G$6*(1+$B10)*(DCF!$H$8*(1-DCF!$H$10)+DCF!$H$13-DCF!$H$15)/(D$8-$B10)/(1+D$8)^DCF!$G$5+DCF!$B$29+DCF!$B$30)/'Dane historyczne'!$B$43,"-") -> 121.66578 | E10: =IF(E$8>$B10,(SUMPRODUCT(DCF!$C$17:$G$17/(1+E$8)^DCF!$C$5:$G$5)+DCF!$G$6*(1+$B10)*(DCF!$H$8*(1-DCF!$H$10)+DCF!$H$13-DCF!$H$15)/(E$8-$B10)/(1+E$8)^DCF!$G$5+DCF!$B$29+DCF!$B$30)/'Dane historyczne'!$B$43,"-") -> 104.46737 | F10: =IF(F$8>$B10,(SUMPRODUCT(DCF!$C$17:$G$17/(1+F$8)^DCF!$C$5:$G$5)+DCF!$G$6*(1+$B10)*(DCF!$H$8*(1-DCF!$H$10)+DCF!$H$13-DCF!$H$15)/(F$8-$B10)/(1+F$8)^DCF!$G$5+DCF!$B$29+DCF!$B$30)/'Dane historyczne'!$B$43,"-") -> 91.15536 | G10: =IF(G$8>$B10,(SUMPRODUCT(DCF!$C$17:$G$17/(1+G$8)^DCF!$C$5:$G$5)+DCF!$G$6*(1+$B10)*(DCF!$H$8*(1-DCF!$H$10)+DCF!$H$13-DCF!$H$15)/(G$8-$B10)/(1+G$8)^DCF!$G$5+DCF!$B$29+DCF!$B$30)/'Dane historyczne'!$B$43,"-") -> 80.570491
B11: =Założenia!$B$18+(0)*$B$5 -> 0.03 | C11: =IF(C$8>$B11,(SUMPRODUCT(DCF!$C$17:$G$17/(1+C$8)^DCF!$C$5:$G$5)+DCF!$G$6*(1+$B11)*(DCF!$H$8*(1-DCF!$H$10)+DCF!$H$13-DCF!$H$15)/(C$8-$B11)/(1+C$8)^DCF!$G$5+DCF!$B$29+DCF!$B$30)/'Dane historyczne'!$B$43,"-") -> 156.54169 | D11: =IF(D$8>$B11,(SUMPRODUCT(DCF!$C$17:$G$17/(1+D$8)^DCF!$C$5:$G$5)+DCF!$G$6*(1+$B11)*(DCF!$H$8*(1-DCF!$H$10)+DCF!$H$13-DCF!$H$15)/(D$8-$B11)/(1+D$8)^DCF!$G$5+DCF!$B$29+DCF!$B$30)/'Dane historyczne'!$B$43,"-") -> 130.00808 | E11: =IF(E$8>$B11,(SUMPRODUCT(DCF!$C$17:$G$17/(1+E$8)^DCF!$C$5:$G$5)+DCF!$G$6*(1+$B11)*(DCF!$H$8*(1-DCF!$H$10)+DCF!$H$13-DCF!$H$15)/(E$8-$B11)/(1+E$8)^DCF!$G$5+DCF!$B$29+DCF!$B$30)/'Dane historyczne'!$B$43,"-") -> 110.59103 | F11: =IF(F$8>$B11,(SUMPRODUCT(DCF!$C$17:$G$17/(1+F$8)^DCF!$C$5:$G$5)+DCF!$G$6*(1+$B11)*(DCF!$H$8*(1-DCF!$H$10)+DCF!$H$13-DCF!$H$15)/(F$8-$B11)/(1+F$8)^DCF!$G$5+DCF!$B$29+DCF!$B$30)/'Dane historyczne'!$B$43,"-") -> 95.801943 | G11: =IF(G$8>$B11,(SUMPRODUCT(DCF!$C$17:$G$17/(1+G$8)^DCF!$C$5:$G$5)+DCF!$G$6*(1+$B11)*(DCF!$H$8*(1-DCF!$H$10)+DCF!$H$13-DCF!$H$15)/(G$8-$B11)/(1+G$8)^DCF!$G$5+DCF!$B$29+DCF!$B$30)/'Dane historyczne'!$B$43,"-") -> 84.189454
B12: =Założenia!$B$18+(1)*$B$5 -> 0.035 | C12: =IF(C$8>$B12,(SUMPRODUCT(DCF!$C$17:$G$17/(1+C$8)^DCF!$C$5:$G$5)+DCF!$G$6*(1+$B12)*(DCF!$H$8*(1-DCF!$H$10)+DCF!$H$13-DCF!$H$15)/(C$8-$B12)/(1+C$8)^DCF!$G$5+DCF!$B$29+DCF!$B$30)/'Dane historyczne'!$B$43,"-") -> 170.74053 | D12: =IF(D$8>$B12,(SUMPRODUCT(DCF!$C$17:$G$17/(1+D$8)^DCF!$C$5:$G$5)+DCF!$G$6*(1+$B12)*(DCF!$H$8*(1-DCF!$H$10)+DCF!$H$13-DCF!$H$15)/(D$8-$B12)/(1+D$8)^DCF!$G$5+DCF!$B$29+DCF!$B$30)/'Dane historyczne'!$B$43,"-") -> 139.71797 | E12: =IF(E$8>$B12,(SUMPRODUCT(DCF!$C$17:$G$17/(1+E$8)^DCF!$C$5:$G$5)+DCF!$G$6*(1+$B12)*(DCF!$H$8*(1-DCF!$H$10)+DCF!$H$13-DCF!$H$15)/(E$8-$B12)/(1+E$8)^DCF!$G$5+DCF!$B$29+DCF!$B$30)/'Dane historyczne'!$B$43,"-") -> 117.57718 | F12: =IF(F$8>$B12,(SUMPRODUCT(DCF!$C$17:$G$17/(1+F$8)^DCF!$C$5:$G$5)+DCF!$G$6*(1+$B12)*(DCF!$H$8*(1-DCF!$H$10)+DCF!$H$13-DCF!$H$15)/(F$8-$B12)/(1+F$8)^DCF!$G$5+DCF!$B$29+DCF!$B$30)/'Dane historyczne'!$B$43,"-") -> 101.02218 | G12: =IF(G$8>$B12,(SUMPRODUCT(DCF!$C$17:$G$17/(1+G$8)^DCF!$C$5:$G$5)+DCF!$G$6*(1+$B12)*(DCF!$H$8*(1-DCF!$H$10)+DCF!$H$13-DCF!$H$15)/(G$8-$B12)/(1+G$8)^DCF!$G$5+DCF!$B$29+DCF!$B$30)/'Dane historyczne'!$B$43,"-") -> 88.206105
B13: =Założenia!$B$18+(2)*$B$5 -> 0.04 | C13: =IF(C$8>$B13,(SUMPRODUCT(DCF!$C$17:$G$17/(1+C$8)^DCF!$C$5:$G$5)+DCF!$G$6*(1+$B13)*(DCF!$H$8*(1-DCF!$H$10)+DCF!$H$13-DCF!$H$15)/(C$8-$B13)/(1+C$8)^DCF!$G$5+DCF!$B$29+DCF!$B$30)/'Dane historyczne'!$B$43,"-") -> 188.02607 | D13: =IF(D$8>$B13,(SUMPRODUCT(DCF!$C$17:$G$17/(1+D$8)^DCF!$C$5:$G$5)+DCF!$G$6*(1+$B13)*(DCF!$H$8*(1-DCF!$H$10)+DCF!$H$13-DCF!$H$15)/(D$8-$B13)/(1+D$8)^DCF!$G$5+DCF!$B$29+DCF!$B$30)/'Dane historyczne'!$B$43,"-") -> 151.16177 | E13: =IF(E$8>$B13,(SUMPRODUCT(DCF!$C$17:$G$17/(1+E$8)^DCF!$C$5:$G$5)+DCF!$G$6*(1+$B13)*(DCF!$H$8*(1-DCF!$H$10)+DCF!$H$13-DCF!$H$15)/(E$8-$B13)/(1+E$8)^DCF!$G$5+DCF!$B$29+DCF!$B$30)/'Dane historyczne'!$B$43,"-") -> 125.62184 | F13: =IF(F$8>$B13,(SUMPRODUCT(DCF!$C$17:$G$17/(1+F$8)^DCF!$C$5:$G$5)+DCF!$G$6*(1+$B13)*(DCF!$H$8*(1-DCF!$H$10)+DCF!$H$13-DCF!$H$15)/(F$8-$B13)/(1+F$8)^DCF!$G$5+DCF!$B$29+DCF!$B$30)/'Dane historyczne'!$B$43,"-") -> 106.92929 | G13: =IF(G$8>$B13,(SUMPRODUCT(DCF!$C$17:$G$17/(1+G$8)^DCF!$C$5:$G$5)+DCF!$G$6*(1+$B13)*(DCF!$H$8*(1-DCF!$H$10)+DCF!$H$13-DCF!$H$15)/(G$8-$B13)/(1+G$8)^DCF!$G$5+DCF!$B$29+DCF!$B$30)/'Dane historyczne'!$B$43,"-") -> 92.689809
A15: Aktualny kurs (USD) | B15: =Założenia!$B$20 -> 336.91
A16: Wartość bazowa (USD) | B16: =DCF!$B$33 -> 110.59103
A17: Kontrola: środek tabeli = wartość bazowa | B17: =IF(ABS(E11-B16)<0.01,"OK","BŁĄD") -> OK

Sheet Ledger
A1: GOOG - ledger: wszystkie wpisy ze źródłem i cytatem
A3: id | B3: klasa | C3: klucz | D3: opis | E3: wartość | F3: jednostka | G3: okres | H3: źródło | I3: strona | J3: adres | K3: cytat / uzasadnienie
A4: F-01 | B4: fakt | C4: revenue_2025 | D4: Przychody ogółem (Revenues) | E4: 402836 | F4: mln USD | G4: 2025 | H4: Alphabet Inc. - raport roczny 10-K za 2025 r. | I4: 49 | J4: https://www.sec.gov/Archives/edgar/data/1652044/000165204426000018/goog-20251231.htm | K4: Revenues $ 307,394 $ 350,018 $ 402,836
A5: F-02 | B5: fakt | C5: revenue_2024 | D5: Przychody ogółem (Revenues) | E5: 350018 | F5: mln USD | G5: 2024 | H5: Alphabet Inc. - raport roczny 10-K za 2025 r. | I5: 49 | J5: https://www.sec.gov/Archives/edgar/data/1652044/000165204426000018/goog-20251231.htm | K5: Revenues $ 307,394 $ 350,018 $ 402,836
A6: F-03 | B6: fakt | C6: revenue_2023 | D6: Przychody ogółem (Revenues) | E6: 307394 | F6: mln USD | G6: 2023 | H6: Alphabet Inc. - raport roczny 10-K za 2025 r. | I6: 49 | J6: https://www.sec.gov/Archives/edgar/data/1652044/000165204426000018/goog-20251231.htm | K6: Revenues $ 307,394 $ 350,018 $ 402,836
A7: F-04 | B7: fakt | C7: operating_income_2025 | D7: Zysk operacyjny (Income from operations) | E7: 129039 | F7: mln USD | G7: 2025 | H7: Alphabet Inc. - raport roczny 10-K za 2025 r. | I7: 49 | J7: https://www.sec.gov/Archives/edgar/data/1652044/000165204426000018/goog-20251231.htm | K7: Income from operations 84,293 112,390 129,039
A8: F-05 | B8: fakt | C8: operating_income_2024 | D8: Zysk operacyjny (Income from operations) | E8: 112390 | F8: mln USD | G8: 2024 | H8: Alphabet Inc. - raport roczny 10-K za 2025 r. | I8: 49 | J8: https://www.sec.gov/Archives/edgar/data/1652044/000165204426000018/goog-20251231.htm | K8: Income from operations 84,293 112,390 129,039
A9: F-06 | B9: fakt | C9: operating_income_2023 | D9: Zysk operacyjny (Income from operations) | E9: 84293 | F9: mln USD | G9: 2023 | H9: Alphabet Inc. - raport roczny 10-K za 2025 r. | I9: 49 | J9: https://www.sec.gov/Archives/edgar/data/1652044/000165204426000018/goog-20251231.htm | K9: Income from operations 84,293 112,390 129,039
A10: F-07 | B10: fakt | C10: net_income_2025 | D10: Zysk netto (Net income) | E10: 132170 | F10: mln USD | G10: 2025 | H10: Alphabet Inc. - raport roczny 10-K za 2025 r. | I10: 49 | J10: https://www.sec.gov/Archives/edgar/data/1652044/000165204426000018/goog-20251231.htm | K10: Net income $ 73,795 $ 100,118 $ 132,170
A11: F-08 | B11: fakt | C11: depreciation_2025 | D11: Amortyzacja rzeczowych aktywów trwałych (Depreciation of property and equipment), rachunek przepływów | E11: 21136 | F11: mln USD | G11: 2025 | H11: Alphabet Inc. - raport roczny 10-K za 2025 r. | I11: 52 | J11: https://www.sec.gov/Archives/edgar/data/1652044/000165204426000018/goog-20251231.htm | K11: Depreciation of property and equipment 11,946 15,311 21,136
A12: F-09 | B12: fakt | C12: capex_2025 | D12: Nakłady inwestycyjne (Purchases of property and equipment), wypływ gotówki | E12: -91447 | F12: mln USD | G12: 2025 | H12: Alphabet Inc. - raport roczny 10-K za 2025 r. | I12: 52 | J12: https://www.sec.gov/Archives/edgar/data/1652044/000165204426000018/goog-20251231.htm | K12: Purchases of property and equipment (32,251) (52,535) (91,447)
A13: F-10 | B13: fakt | C13: income_before_tax_2025 | D13: Zysk przed opodatkowaniem (Income before income taxes) | E13: 158826 | F13: mln USD | G13: 2025 | H13: Alphabet Inc. - raport roczny 10-K za 2025 r. | I13: 49 | J13: https://www.sec.gov/Archives/edgar/data/1652044/000165204426000018/goog-20251231.htm | K13: Income before income taxes 85,717 119,815 158,826
A14: F-11 | B14: fakt | C14: income_tax_2025 | D14: Podatek dochodowy (Provision for income taxes) | E14: 26656 | F14: mln USD | G14: 2025 | H14: Alphabet Inc. - raport roczny 10-K za 2025 r. | I14: 49 | J14: https://www.sec.gov/Archives/edgar/data/1652044/000165204426000018/goog-20251231.htm | K14: Provision for income taxes 11,922 19,697 26,656
A15: F-12 | B15: fakt | C15: cash_and_equivalents_2025 | D15: Gotówka i ekwiwalenty (Cash and cash equivalents) na koniec roku | E15: 30708 | F15: mln USD | G15: 2025-12-31 | H15: Alphabet Inc. - raport roczny 10-K za 2025 r. | I15: 48 | J15: https://www.sec.gov/Archives/edgar/data/1652044/000165204426000018/goog-20251231.htm | K15: Cash and cash equivalents $ 23,466 $ 30,708
... A31: F-28 | B31: fakt | C31: segment_revenue_google_cloud_2024 | D31: Przychody segmentu Google Cloud | E31: 43229 | F31: mln USD | G31: 2024 | H31: Alphabet Inc. - raport roczny 10-K za 2025 r. | I31: 33 | J31: https://www.sec.gov/Archives/edgar/data/1652044/000165204426000018/goog-20251231.htm | K31: Google Cloud 43,229 58,705
A32: F-29 | B32: fakt | C32: ai_model_gemini_3 | D32: Gemini 3 - według spółki jej najbardziej inteligentny model AI | E32: Gemini 3 | F32: n/d | G32: 2025 | H32: Alphabet Inc. - raport roczny 10-K za 2025 r. | I32: 4 | J32: https://www.sec.gov/Archives/edgar/data/1652044/000165204426000018/goog-20251231.htm | K32: Over the last decade, our research teams have pushed the boundaries of AI forward, which is displayed through Gemini 3, our most intelligent AI model yet.
A33: F-30 | B33: fakt | C33: gemini_half_billion_user_products | D33: Liczba produktów Google z ponad pół miliardem użytkowników, które korzystają z modeli Gemini (wszystkie takie produkty) | E33: 15 | F33: szt. | G33: stan w raporcie (luty 2026) | H33: Alphabet Inc. - raport roczny 10-K za 2025 r. | I33: 4 | J33: https://www.sec.gov/Archives/edgar/data/1652044/000165204426000018/goog-20251231.htm | K33: Today, all 15 of our half-billion-user products — including seven with two billion users — use our Gemini models.
A34: F-31 | B34: fakt | C34: tpu_ironwood | D34: Ironwood - własny układ AI Google (TPU) siódmej generacji | E34: Ironwood | F34: n/d | G34: stan w raporcie (luty 2026) | H34: Alphabet Inc. - raport roczny 10-K za 2025 r. | I34: 4 | J34: https://www.sec.gov/Archives/edgar/data/1652044/000165204426000018/goog-20251231.htm | K34: our own custom-built Tensor Processing Units (TPUs), such as Ironwood, our seventh-generation TPU.
A35: F-32 | B35: fakt | C35: revenue_backlog_2025 | D35: Portfel zamówień (remaining performance obligations, revenue backlog), głównie Google Cloud, na koniec roku | E35: 242.8 | F35: mld USD | G35: 2025-12-31 | H35: Alphabet Inc. - raport roczny 10-K za 2025 r. | I35: 60 | J35: https://www.sec.gov/Archives/edgar/data/1652044/000165204426000018/goog-20251231.htm | K35: As of December 31, 2025, we had $242.8 billion of remaining performance obligations (“revenue backlog"), primarily related to Google Cloud.
A36: F-33 | B36: fakt | C36: waymo_paid_rides | D36: Waymo świadczy w pełni autonomiczne, płatne przejazdy w wielu miastach | E36: płatne przejazdy autonomiczne | F36: n/d | G36: stan w raporcie (luty 2026) | H36: Alphabet Inc. - raport roczny 10-K za 2025 r. | I36: 4 | J36: https://www.sec.gov/Archives/edgar/data/1652044/000165204426000018/goog-20251231.htm | K36: In Other Bets, our fully autonomous driving technology company, Waymo, is now providing fully autonomous, paid ride-hailing services to customers in multiple cities.
A37: F-34 | B37: fakt | C37: waymo_investment_round_2026 | D37: Runda finansowania Waymo ogłoszona w lutym 2026 r., w większości sfinansowana przez Alphabet | E37: 16 | F37: mld USD | G37: 2026-02 | H37: Alphabet Inc. - raport roczny 10-K za 2025 r. | I37: 33 | J37: https://www.sec.gov/Archives/edgar/data/1652044/000165204426000018/goog-20251231.htm | K37: In February 2026, Waymo announced an investment round of $16.0 billion, the significant majority of which was funded by Alphabet.
A38: F-35 | B38: fakt | C38: wiz_acquisition_price | D38: Cena przejęcia Wiz (platforma bezpieczeństwa chmury), umowa z 2025 r. | E38: 32 | F38: mld USD | G38: 2025 | H38: Alphabet Inc. - raport roczny 10-K za 2025 r. | I38: 33 | J38: https://www.sec.gov/Archives/edgar/data/1652044/000165204426000018/goog-20251231.htm | K38: In 2025, we entered into definitive agreements to acquire Wiz, a leading cloud security platform, for $32.0 billion
A39: F-36 | B39: fakt | C39: capex_plan_2026 | D39: Plan nakładów na 2026 r.: znaczący wzrost inwestycji w infrastrukturę techniczną wobec 2025 r. (raport nie podaje kwoty) | E39: znaczący wzrost | F39: n/d | G39: 2026 | H39: Alphabet Inc. - raport roczny 10-K za 2025 r. | I39: 38 | J39: https://www.sec.gov/Archives/edgar/data/1652044/000165204426000018/goog-20251231.htm | K39: In 2026, we expect to significantly increase, relative to 2025, our investment in our technical infrastructure, including servers and network equipment, and data centers.
A40: F-37 | B40: fakt | C40: advertising_revenue_share_2025 | D40: Udział reklamy online w przychodach ogółem: ponad 70% | E40: 70 | F40: % | G40: 2025 | H40: Alphabet Inc. - raport roczny 10-K za 2025 r. | I40: 9 | J40: https://www.sec.gov/Archives/edgar/data/1652044/000165204426000018/goog-20251231.htm | K40: We generated more than 70% of total revenues from online advertising in 2025.
A41: F-38 | B41: fakt | C41: employees_2025 | D41: Liczba pracowników na koniec roku | E41: 190820 | F41: osób | G41: 2025-12-31 | H41: Alphabet Inc. - raport roczny 10-K za 2025 r. | I41: 33 | J41: https://www.sec.gov/Archives/edgar/data/1652044/000165204426000018/goog-20251231.htm | K41: As of December 31, 2025, we had 190,820 employees.
A42: F-39 | B42: fakt | C42: risk_advertising | D42: Ryzyko: duża część przychodów pochodzi z reklam; mniejsze wydatki reklamodawców, utrata partnerów, zmiany w reklamie online lub blokowanie reklam mogą zaszkodzić biznesowi | E42: zależność od reklam | F42: n/d | G42: 2025 | H42: Alphabet Inc. - raport roczny 10-K za 2025 r. | I42: 9 | J42: https://www.sec.gov/Archives/edgar/data/1652044/000165204426000018/goog-20251231.htm | K42: We generate a significant portion of our revenues from advertising. Reduced spending by advertisers, a loss of partners, shifts in online advertising, new and evolving advertising formats, or new or existing technologies that block ads online or affect our ability to personalize ads could harm our business.
A43: F-40 | B43: fakt | C43: risk_ai_investment | D43: Ryzyko: rosnące inwestycje w nowe biznesy, produkty i technologie są z natury ryzykowne i mogą zaszkodzić wynikom | E43: ryzykowne inwestycje w nowe obszary (w tym AI) | F43: n/d | G43: 2025 | H43: Alphabet Inc. - raport roczny 10-K za 2025 r. | I43: 9 | J43: https://www.sec.gov/Archives/edgar/data/1652044/000165204426000018/goog-20251231.htm | K43: Our increasing investment in new businesses, products, services, and technologies is inherently risky, and could divert management attention and harm our business, financial condition, and operating results.
A44: F-41 | B44: fakt | C44: risk_legal_regulatory | D44: Ryzyko: pozwy, postępowania regulacyjne i antymonopolowe mogą zaszkodzić biznesowi, reputacji i wynikom | E44: spory prawne i regulacje (w tym konkurencja) | F44: n/d | G44: 2025 | H44: Alphabet Inc. - raport roczny 10-K za 2025 r. | I44: 18 | J44: https://www.sec.gov/Archives/edgar/data/1652044/000165204426000018/goog-20251231.htm | K44: We are and may continue to be subject to claims, lawsuits, regulatory and government inquiries and investigations, enforcement actions, consent orders, and other forms of regulatory scrutiny and legal liability, including competition matters, that could harm our business, reputation, financial condition, and operating results.
A45: R-01 | B45: dana_rynkowa | C45: share_price | D45: Kurs zamknięcia akcji GOOG (klasa C, Nasdaq), ostatnia sesja; zaokrąglony do centów | E45: 336.91 | F45: USD | G45: 2026-10-16 | H45: Yahoo Finance - chart API (odpowiedź JSON) | I45: n/d (www) | J45: https://query1.finance.yahoo.com/v8/finance/chart/GOOG?range=5d&interval=1d | K45: "close": [ 348.9700012207031, 349.5199890136719, 343.6499938964844, 344.9100036621094, 336.9100036621094 ]
A46: R-02 | B46: dana_rynkowa | C46: us_treasury_10y_yield | D46: Rentowność 10-letnich obligacji skarbowych USA (seria DGS10) | E46: 5.1 | F46: % | G46: 2026-10-15 | H46: FRED, Federal Reserve Bank of St. Louis - seria DGS10 (CSV) | I46: n/d (www) | J46: https://fred.stlouisfed.org/graph/fredgraph.csv?id=DGS10 | K46: 2026-10-15,5.10
A47: Z-01 | B47: zalozenie | C47: revenue_growth_2026 | D47: Wzrost przychodów r/r w 2026 r. | E47: 14 | F47: % | G47: 2026 | K47: Przychody rosły o ok. 14% w 2024 r. (F-03 -> F-02) i ok. 15% w 2025 r. (F-02 -> F-01). Zakładamy podobne tempo w 2026 r., wspierane przez szybko rosnący Google Cloud (F-28 -> F-23) i duży portfel zamówień (F-32).
A48: Z-02 | B48: zalozenie | C48: revenue_growth_2027 | D48: Wzrost przychodów r/r w 2027 r. | E48: 12 | F48: % | G48: 2027 | K48: Stopniowe spowolnienie: ponad 70% przychodów to reklama online (F-37), a ten rynek rośnie wolniej niż chmura.
A49: Z-03 | B49: zalozenie | C49: revenue_growth_2028 | D49: Wzrost przychodów r/r w 2028 r. | E49: 10 | F49: % | G49: 2028 | K49: Wzrost dalej słabnie wraz ze skalą biznesu; Google Cloud (F-23) rośnie szybciej, ale jest wciąż znacznie mniejszy niż Google Services (F-22).
A50: Z-04 | B50: zalozenie | C50: revenue_growth_2029 | D50: Wzrost przychodów r/r w 2029 r. | E50: 8 | F50: % | G50: 2029 | K50: Kontynuacja łagodnego spowolnienia w stronę dojrzałej spółki.
A51: Z-05 | B51: zalozenie | C51: revenue_growth_2030 | D51: Wzrost przychodów r/r w 2030 r. | E51: 6 | F51: % | G51: 2030 | K51: Ostatni rok prognozy; wzrost zbliża się do poziomu, z którego da się przejść do okresu rezydualnego (Z-25).
A52: Z-06 | B52: zalozenie | C52: operating_margin_2026 | D52: Marża operacyjna w 2026 r. | E52: 31 | F52: % | G52: 2026 | K52: Marża operacyjna wyniosła ok. 32% w 2024 i 2025 r. (F-05/F-02, F-04/F-01), przy amortyzacji ok. 5% przychodów (F-08). Rosnąca amortyzacja (Z-17 do Z-21) obniża marżę o kilka punktów, częściowo równoważy to rosnąca rentowność Google Cloud (F-26) i mniejsza strata Other Bets niż w 2025 r. (F-27).
A53: Z-07 | B53: zalozenie | C53: operating_margin_2027 | D53: Marża operacyjna w 2027 r. | E53: 30 | F53: % | G53: 2027 | K53: Marża operacyjna wyniosła ok. 32% w 2024 i 2025 r. (F-05/F-02, F-04/F-01), przy amortyzacji ok. 5% przychodów (F-08). Rosnąca amortyzacja (Z-17 do Z-21) obniża marżę o kilka punktów, częściowo równoważy to rosnąca rentowność Google Cloud (F-26) i mniejsza strata Other Bets niż w 2025 r. (F-27).
A54: Z-08 | B54: zalozenie | C54: operating_margin_2028 | D54: Marża operacyjna w 2028 r. | E54: 29 | F54: % | G54: 2028 | K54: Marża operacyjna wyniosła ok. 32% w 2024 i 2025 r. (F-05/F-02, F-04/F-01), przy amortyzacji ok. 5% przychodów (F-08). Rosnąca amortyzacja (Z-17 do Z-21) obniża marżę o kilka punktów, częściowo równoważy to rosnąca rentowność Google Cloud (F-26) i mniejsza strata Other Bets niż w 2025 r. (F-27).
A55: Z-09 | B55: zalozenie | C55: operating_margin_2029 | D55: Marża operacyjna w 2029 r. | E55: 29 | F55: % | G55: 2029 | K55: Marża operacyjna wyniosła ok. 32% w 2024 i 2025 r. (F-05/F-02, F-04/F-01), przy amortyzacji ok. 5% przychodów (F-08). Rosnąca amortyzacja (Z-17 do Z-21) obniża marżę o kilka punktów, częściowo równoważy to rosnąca rentowność Google Cloud (F-26) i mniejsza strata Other Bets niż w 2025 r. (F-27).
A56: Z-10 | B56: zalozenie | C56: operating_margin_2030 | D56: Marża operacyjna w 2030 r. | E56: 29 | F56: % | G56: 2030 | K56: Marża operacyjna wyniosła ok. 32% w 2024 i 2025 r. (F-05/F-02, F-04/F-01), przy amortyzacji ok. 5% przychodów (F-08). Rosnąca amortyzacja (Z-17 do Z-21) obniża marżę o kilka punktów, częściowo równoważy to rosnąca rentowność Google Cloud (F-26) i mniejsza strata Other Bets niż w 2025 r. (F-27).
...
